Workbook
Name _: #REF!
Name _: #REF!
Name _: #REF!
Name _: #REF!
Name _: #REF!
Name _______l: #REF!
Name _______l: #REF!
Name ____l: #REF!
Name ____l: #REF!
Name ___KEY2: #REF!
Name ___KEY2: #REF!
Name ___KEY2: #REF!
Name ___KEY2: #REF!
Name ___KEY2: #REF!
Name ___l: #REF!
Name ___l: #REF!
Name __123Graph_A: #REF!
Name __123Graph_A: #REF!
Name __123Graph_A: #REF!
Name __123Graph_A: #REF!
Name __123Graph_A: #REF!
Name __123Graph_ABUDGET: #REF!
Name __123Graph_ABUDGET: #REF!
Name __123Graph_ABUDGET: #REF!
Name __123Graph_ABUDGET: #REF!
Name __123Graph_ABUDGET: #REF!
Name __123Graph_ACorrente: #REF!
Name __123Graph_ACorrente: #REF!
Name __123Graph_ACorrente: #REF!
Name __123Graph_ACorrente: #REF!
Name __123Graph_ACorrente: #REF!
Name __123Graph_ACURRENT: #REF!
Name __123Graph_ACURRENT: #REF!
Name __123Graph_ACURRENT: #REF!
Name __123Graph_ACURRENT: #REF!
Name __123Graph_ACURRENT: #REF!
Name __123Graph_APRIOR: #REF!
Name __123Graph_APRIOR: #REF!
Name __123Graph_APRIOR: #REF!
Name __123Graph_APRIOR: #REF!
Name __123Graph_APRIOR: #REF!
Name __123Graph_B: #REF!
Name __123Graph_B: #REF!
Name __123Graph_B: #REF!
Name __123Graph_B: #REF!
Name __123Graph_B: #REF!
Name __123Graph_BBUDGET: #REF!
Name __123Graph_BBUDGET: #REF!
Name __123Graph_BBUDGET: #REF!
Name __123Graph_BBUDGET: #REF!
Name __123Graph_BBUDGET: #REF!
Name __123Graph_BCorrente: #REF!
Name __123Graph_BCorrente: #REF!
Name __123Graph_BCorrente: #REF!
Name __123Graph_BCorrente: #REF!
Name __123Graph_BCorrente: #REF!
Name __123Graph_BCURRENT: #REF!
Name __123Graph_BCURRENT: #REF!
Name __123Graph_BCURRENT: #REF!
Name __123Graph_BCURRENT: #REF!

Sheet PREÇO NACIONAL
B1: PREÇO PARA PUBLICAÇÃO - MAR.26
B2: a cada 10.000 Km ou 1 ano
B3: Ano / Modelo | C3: 1ª revisão | D3: 2ª revisão | E3: 3ª revisão | F3: 4ª revisão | G3: 5ª revisão | H3: 6ª revisão | I3: 7ª revisão | J3: 8ª revisão | K3: 9ª revisão | L3: 10ª revisão
B4: ='NOVO UNO 1.0 FIRE'!A1 -> UNO 1.0 FIRE | C4: ='NOVO UNO 1.0 FIRE'!O2 -> #N/A | D4: ='NOVO UNO 1.0 FIRE'!P2 -> #N/A | E4: ='NOVO UNO 1.0 FIRE'!Q2 -> #N/A | F4: ='NOVO UNO 1.0 FIRE'!R2 -> #N/A | G4: ='NOVO UNO 1.0 FIRE'!S2 -> #N/A | H4: ='NOVO UNO 1.0 FIRE'!T2 -> #N/A | I4: ='NOVO UNO 1.0 FIRE'!U2 -> #N/A | J4: ='NOVO UNO 1.0 FIRE'!V2 -> #N/A | ... L4: ='NOVO UNO 1.0 FIRE'!X2 -> #N/A | M4: =SUM(C4:L4) -> #N/A | N4: =SUM(C4:H4) -> #N/A
B5: ='NOVO UNO 1.0 FIREFLY'!A1 -> UNO 1.0 FIREFLY | C5: ='NOVO UNO 1.0 FIREFLY'!O2 -> #N/A | D5: ='NOVO UNO 1.0 FIREFLY'!P2 -> #N/A | E5: ='NOVO UNO 1.0 FIREFLY'!Q2 -> #N/A | F5: ='NOVO UNO 1.0 FIREFLY'!R2 -> #N/A | G5: ='NOVO UNO 1.0 FIREFLY'!S2 -> #N/A | H5: ='NOVO UNO 1.0 FIREFLY'!T2 -> #N/A | I5: ='NOVO UNO 1.0 FIREFLY'!U2 -> #N/A | J5: ='NOVO UNO 1.0 FIREFLY'!V2 -> #N/A | ... L5: ='NOVO UNO 1.0 FIREFLY'!X2 -> #N/A | M5: =SUM(C5:L5) -> #N/A | N5: =SUM(C5:H5) -> #N/A
B6: ='NOVO UNO 1.3 FIREFLY'!A1 -> UNO 1.3 FIREFLY | C6: ='NOVO UNO 1.3 FIREFLY'!O2 -> #N/A | D6: ='NOVO UNO 1.3 FIREFLY'!P2 -> #N/A | E6: ='NOVO UNO 1.3 FIREFLY'!Q2 -> #N/A | F6: ='NOVO UNO 1.3 FIREFLY'!R2 -> #N/A | G6: ='NOVO UNO 1.3 FIREFLY'!S2 -> #N/A | H6: ='NOVO UNO 1.3 FIREFLY'!T2 -> #N/A | I6: ='NOVO UNO 1.3 FIREFLY'!U2 -> #N/A | J6: ='NOVO UNO 1.3 FIREFLY'!V2 -> #N/A | ... L6: ='NOVO UNO 1.3 FIREFLY'!X2 -> #N/A | M6: =SUM(C6:L6) -> #N/A | N6: =SUM(C6:H6) -> #N/A
B7: ='PALIO WEEKEND 1.4'!A1 -> PALIO WEEKEND 1.4 | C7: ='PALIO WEEKEND 1.4'!O2 -> #N/A | D7: ='PALIO WEEKEND 1.4'!P2 -> #N/A | E7: ='PALIO WEEKEND 1.4'!Q2 -> #N/A | F7: ='PALIO WEEKEND 1.4'!R2 -> #N/A | G7: ='PALIO WEEKEND 1.4'!S2 -> #N/A | H7: ='PALIO WEEKEND 1.4'!T2 -> #N/A | I7: ='PALIO WEEKEND 1.4'!U2 -> #N/A | J7: ='PALIO WEEKEND 1.4'!V2 -> #N/A | ... L7: ='PALIO WEEKEND 1.4'!X2 -> #N/A | M7: =SUM(C7:L7) -> #N/A | N7: =SUM(C7:H7) -> #N/A
B8: ='PALIO WEEKEND 1.8'!A1 -> PALIO WEEKEND 1.8 | C8: ='PALIO WEEKEND 1.8'!O2 -> #N/A | D8: ='PALIO WEEKEND 1.8'!P2 -> #N/A | E8: ='PALIO WEEKEND 1.8'!Q2 -> #N/A | F8: ='PALIO WEEKEND 1.8'!R2 -> #N/A | G8: ='PALIO WEEKEND 1.8'!S2 -> #N/A | H8: ='PALIO WEEKEND 1.8'!T2 -> #N/A | I8: ='PALIO WEEKEND 1.8'!U2 -> #N/A | J8: ='PALIO WEEKEND 1.8'!V2 -> #N/A | ... L8: ='PALIO WEEKEND 1.8'!X2 -> #N/A | M8: =SUM(C8:L8) -> #N/A | N8: =SUM(C8:H8) -> #N/A
B9: =FIORINO!A15 -> FIORINO 1.4 (21/22) | C9: =FIORINO!T16 -> #N/A | D9: =FIORINO!U16 -> #N/A | E9: =FIORINO!V16 -> #N/A | F9: =FIORINO!W16 -> #N/A | G9: =FIORINO!X16 -> #N/A | H9: =FIORINO!Y16 -> #N/A | I9: =FIORINO!Z16 -> #N/A | J9: =FIORINO!AA16 -> #N/A | ... L9: =FIORINO!AC16 -> #N/A | M9: =SUM(C9:L9) -> #N/A | N9: =SUM(C9:H9) -> #N/A
B10: =FIORINO!A1 -> FIORINO 1.4 (21/21) | C10: =FIORINO!T2 -> #N/A | D10: =FIORINO!U2 -> #N/A | E10: =FIORINO!V2 -> #N/A | F10: =FIORINO!W2 -> #N/A | G10: =FIORINO!X2 -> #N/A | H10: =FIORINO!Y2 -> #N/A | I10: =FIORINO!Z2 -> #N/A | J10: =FIORINO!AA2 -> #N/A | ... L10: =FIORINO!AC2 -> #N/A | M10: =SUM(C10:L10) -> #N/A | N10: =SUM(C10:H10) -> #N/A
B11: =FIORINO!A30 -> FIORINO 1.3 | C11: =FIORINO!T31 -> #N/A | D11: =FIORINO!U31 -> #N/A | E11: =FIORINO!V31 -> #N/A | F11: =FIORINO!W31 -> #N/A | G11: =FIORINO!X31 -> #N/A | H11: =FIORINO!Y31 -> #N/A | I11: =FIORINO!Z31 -> #N/A | J11: =FIORINO!AA31 -> #N/A | ... L11: =FIORINO!AC31 -> #N/A | M11: =SUM(C11:L11) -> #N/A | N11: =SUM(C11:H11) -> #N/A
B12: ='NOVA STRADA 1.3'!A1 -> NOVA STRADA 1.3 AT | C12: ='NOVA STRADA 1.3'!T2 -> #N/A | D12: ='NOVA STRADA 1.3'!U2 -> #N/A | E12: ='NOVA STRADA 1.3'!V2 -> #N/A | F12: ='NOVA STRADA 1.3'!W2 -> #N/A | G12: ='NOVA STRADA 1.3'!X2 -> #N/A | H12: ='NOVA STRADA 1.3'!Y2 -> #N/A | I12: ='NOVA STRADA 1.3'!Z2 -> #N/A | J12: ='NOVA STRADA 1.3'!AA2 -> #N/A | ... L12: ='NOVA STRADA 1.3'!AC2 -> #N/A | M12: =SUM(C12:L12) -> #N/A | N12: =SUM(C12:H12) -> #N/A
B13: ='NOVA STRADA 1.4'!A1 -> NOVA STRADA 1.4 | C13: ='NOVA STRADA 1.4'!T2 -> #N/A | D13: ='NOVA STRADA 1.4'!U2 -> #N/A | E13: ='NOVA STRADA 1.4'!V2 -> #N/A | F13: ='NOVA STRADA 1.4'!W2 -> #N/A | G13: ='NOVA STRADA 1.4'!X2 -> #N/A | H13: ='NOVA STRADA 1.4'!Y2 -> #N/A | I13: ='NOVA STRADA 1.4'!Z2 -> #N/A | J13: ='NOVA STRADA 1.4'!AA2 -> #N/A | ... L13: ='NOVA STRADA 1.4'!AC2 -> #N/A | M13: =SUM(C13:L13) -> #N/A | N13: =SUM(C13:H13) -> #N/A
B14: ='NOVA STRADA 1.0T'!A1 -> NOVA STRADA 1.0T | C14: ='NOVA STRADA 1.0T'!T2 -> #N/A | D14: ='NOVA STRADA 1.0T'!U2 -> #N/A | E14: ='NOVA STRADA 1.0T'!V2 -> #N/A | F14: ='NOVA STRADA 1.0T'!W2 -> #N/A | G14: ='NOVA STRADA 1.0T'!X2 -> #N/A | H14: ='NOVA STRADA 1.0T'!Y2 -> #N/A | I14: ='NOVA STRADA 1.0T'!Z2 -> #N/A | J14: ='NOVA STRADA 1.0T'!AA2 -> #N/A | ... L14: ='NOVA STRADA 1.0T'!AC2 -> #N/A | M14: =SUM(C14:L14) -> #N/A | N14: =SUM(C14:H14) -> #N/A
B15: ='ARGO 1.0'!A1 -> ARGO 1.0 | C15: ='ARGO 1.0'!T2 -> #N/A | D15: ='ARGO 1.0'!U2 -> #N/A | E15: ='ARGO 1.0'!V2 -> #N/A | F15: ='ARGO 1.0'!W2 -> #N/A | G15: ='ARGO 1.0'!X2 -> #N/A | H15: ='ARGO 1.0'!Y2 -> #N/A | I15: ='ARGO 1.0'!Z2 -> #N/A | J15: ='ARGO 1.0'!AA2 -> #N/A | ... L15: ='ARGO 1.0'!AC2 -> #N/A | M15: =SUM(C15:L15) -> #N/A | N15: =SUM(C15:H15) -> #N/A
B16: ='ARGO 1.3'!A1 -> ARGO 1.3 | C16: ='ARGO 1.3'!T2 -> #N/A | D16: ='ARGO 1.3'!U2 -> #N/A | E16: ='ARGO 1.3'!V2 -> #N/A | F16: ='ARGO 1.3'!W2 -> #N/A | G16: ='ARGO 1.3'!X2 -> #N/A | H16: ='ARGO 1.3'!Y2 -> #N/A | I16: ='ARGO 1.3'!Z2 -> #N/A | J16: ='ARGO 1.3'!AA2 -> #N/A | ... L16: ='ARGO 1.3'!AC2 -> #N/A | M16: =SUM(C16:L16) -> #N/A | N16: =SUM(C16:H16) -> #N/A
B17: ='ARGO 1.8'!A1 -> ARGO 1.8 | C17: ='ARGO 1.8'!O2 -> #N/A | D17: ='ARGO 1.8'!P2 -> #N/A | E17: ='ARGO 1.8'!Q2 -> #N/A | F17: ='ARGO 1.8'!R2 -> #N/A | G17: ='ARGO 1.8'!S2 -> #N/A | H17: ='ARGO 1.8'!T2 -> #N/A | I17: ='ARGO 1.8'!U2 -> #N/A | J17: ='ARGO 1.8'!V2 -> #N/A | ... L17: ='ARGO 1.8'!X2 -> #N/A | M17: =SUM(C17:L17) -> #N/A | N17: =SUM(C17:H17) -> #N/A
B18: ='GRAND SIENA 1.0'!A1 -> GRAND SIENA 1.0 | C18: ='GRAND SIENA 1.0'!O2 -> #N/A | D18: ='GRAND SIENA 1.0'!P2 -> #N/A | E18: ='GRAND SIENA 1.0'!Q2 -> #N/A | F18: ='GRAND SIENA 1.0'!R2 -> #N/A | G18: ='GRAND SIENA 1.0'!S2 -> #N/A | H18: ='GRAND SIENA 1.0'!T2 -> #N/A | I18: ='GRAND SIENA 1.0'!U2 -> #N/A | J18: ='GRAND SIENA 1.0'!V2 -> #N/A | ... L18: ='GRAND SIENA 1.0'!X2 -> #N/A | M18: =SUM(C18:L18) -> #N/A | N18: =SUM(C18:H18) -> #N/A
B19: ='GRAND SIENA 1.4'!A1 -> GRAND SIENA 1.4 | C19: ='GRAND SIENA 1.4'!O2 -> #N/A | D19: ='GRAND SIENA 1.4'!P2 -> #N/A | E19: ='GRAND SIENA 1.4'!Q2 -> #N/A | F19: ='GRAND SIENA 1.4'!R2 -> #N/A | G19: ='GRAND SIENA 1.4'!S2 -> #N/A | H19: ='GRAND SIENA 1.4'!T2 -> #N/A | I19: ='GRAND SIENA 1.4'!U2 -> #N/A | J19: ='GRAND SIENA 1.4'!V2 -> #N/A | ... L19: ='GRAND SIENA 1.4'!X2 -> #N/A | M19: =SUM(C19:L19) -> #N/A | N19: =SUM(C19:H19) -> #N/A
B20: ='MOBI FIRE'!A1 -> MOBI 1.0 FIRE | C20: ='MOBI FIRE'!T2 -> #N/A | D20: ='MOBI FIRE'!U2 -> #N/A | E20: ='MOBI FIRE'!V2 -> #N/A | F20: ='MOBI FIRE'!W2 -> #N/A | G20: ='MOBI FIRE'!X2 -> #N/A | H20: ='MOBI FIRE'!Y2 -> #N/A | I20: ='MOBI FIRE'!Z2 -> #N/A | J20: ='MOBI FIRE'!AA2 -> #N/A | ... L20: ='MOBI FIRE'!AC2 -> #N/A | M20: =SUM(C20:L20) -> #N/A | N20: =SUM(C20:H20) -> #N/A
B21: ='MOBI FIREFLY'!A1 -> MOBI FIREFLY | C21: ='MOBI FIREFLY'!T2 -> #N/A | D21: ='MOBI FIREFLY'!U2 -> #N/A | E21: ='MOBI FIREFLY'!V2 -> #N/A | F21: ='MOBI FIREFLY'!W2 -> #N/A | G21: ='MOBI FIREFLY'!X2 -> #N/A | H21: ='MOBI FIREFLY'!Y2 -> #N/A | I21: ='MOBI FIREFLY'!Z2 -> #N/A | J21: ='MOBI FIREFLY'!AA2 -> #N/A | ... L21: ='MOBI FIREFLY'!AC2 -> #N/A | M21: =SUM(C21:L21) -> #N/A | N21: =SUM(C21:H21) -> #N/A
B22: =DOBLO!A1 -> DOBLO 1.8 | C22: =DOBLO!O2 -> 427 | D22: =DOBLO!P2 -> #N/A | E22: =DOBLO!Q2 -> #N/A | F22: =DOBLO!R2 -> #N/A | G22: =DOBLO!S2 -> #N/A | H22: =DOBLO!T2 -> #N/A | I22: =DOBLO!U2 -> #N/A | J22: =DOBLO!V2 -> #N/A | ... L22: =DOBLO!X2 -> #N/A | M22: =SUM(C22:L22) -> #N/A | N22: =SUM(C22:H22) -> #N/A
B23: ='CRONOS 1.0'!A1 -> CRONOS 1.0 até MY26 | C23: ='CRONOS 1.0'!T2 -> #N/A | D23: ='CRONOS 1.0'!U2 -> #N/A | E23: ='CRONOS 1.0'!V2 -> #N/A | F23: ='CRONOS 1.0'!W2 -> #N/A | G23: ='CRONOS 1.0'!X2 -> #N/A | H23: ='CRONOS 1.0'!Y2 -> #N/A | I23: ='CRONOS 1.0'!Z2 -> #N/A | J23: ='CRONOS 1.0'!AA2 -> #N/A | ... L23: ='CRONOS 1.0'!AC2 -> #N/A | M23: =SUM(C23:L23) -> #N/A | N23: =SUM(C23:H23) -> #N/A
B24: ='CRONOS 1.3'!A1 -> CRONOS 1.3 até MY26 | C24: ='CRONOS 1.3'!T2 -> #N/A | D24: ='CRONOS 1.3'!U2 -> #N/A | E24: ='CRONOS 1.3'!V2 -> #N/A | F24: ='CRONOS 1.3'!W2 -> #N/A | G24: ='CRONOS 1.3'!X2 -> #N/A | H24: ='CRONOS 1.3'!Y2 -> #N/A | I24: ='CRONOS 1.3'!Z2 -> #N/A | J24: ='CRONOS 1.3'!AA2 -> #N/A | ... L24: ='CRONOS 1.3'!AC2 -> #N/A | M24: =SUM(C24:L24) -> #N/A | N24: =SUM(C24:H24) -> #N/A
B25: ='CRONOS 1.8'!A1 -> CRONOS 1.8 | C25: ='CRONOS 1.8'!T2 -> #N/A | D25: ='CRONOS 1.8'!U2 -> #N/A | E25: ='CRONOS 1.8'!V2 -> #N/A | F25: ='CRONOS 1.8'!W2 -> #N/A | G25: ='CRONOS 1.8'!X2 -> #N/A | H25: ='CRONOS 1.8'!Y2 -> #N/A | I25: ='CRONOS 1.8'!Z2 -> #N/A | J25: ='CRONOS 1.8'!AA2 -> #N/A | ... L25: ='CRONOS 1.8'!AC2 -> #N/A | M25: =SUM(C25:L25) -> #N/A | N25: =SUM(C25:H25) -> #N/A
B26: ='PULSE 1.0T'!A1 -> PULSE 1.0T AT | C26: ='PULSE 1.0T'!T2 -> #N/A | D26: ='PULSE 1.0T'!U2 -> #N/A | E26: ='PULSE 1.0T'!V2 -> #N/A | F26: ='PULSE 1.0T'!W2 -> #N/A | G26: ='PULSE 1.0T'!X2 -> #N/A | H26: ='PULSE 1.0T'!Y2 -> #N/A | I26: ='PULSE 1.0T'!Z2 -> #N/A | J26: ='PULSE 1.0T'!AA2 -> #N/A | ... L26: ='PULSE 1.0T'!AC2 -> #N/A | M26: =SUM(C26:L26) -> #N/A | N26: =SUM(C26:H26) -> #N/A
B27: ='PULSE 1.3'!A1 -> PULSE 1.3 AT | C27: ='PULSE 1.3'!T2 -> #N/A | D27: ='PULSE 1.3'!U2 -> #N/A | E27: ='PULSE 1.3'!V2 -> #N/A | F27: ='PULSE 1.3'!W2 -> #N/A | G27: ='PULSE 1.3'!X2 -> #N/A | H27: ='PULSE 1.3'!Y2 -> #N/A | I27: ='PULSE 1.3'!Z2 -> #N/A | J27: ='PULSE 1.3'!AA2 -> #N/A | ... L27: ='PULSE 1.3'!AC2 -> #N/A | M27: =SUM(C27:L27) -> #N/A | N27: =SUM(C27:H27) -> #N/A
B28: ='PULSE ABARTH'!A1 -> PULSE ABARTH 1.3T | C28: ='PULSE ABARTH'!O2 -> #N/A | D28: ='PULSE ABARTH'!P2 -> #N/A | E28: ='PULSE ABARTH'!Q2 -> #N/A | F28: ='PULSE ABARTH'!R2 -> #N/A | G28: ='PULSE ABARTH'!S2 -> #N/A | H28: ='PULSE ABARTH'!T2 -> #N/A | I28: ='PULSE ABARTH'!U2 -> #N/A | J28: ='PULSE ABARTH'!V2 -> #N/A | ... L28: ='PULSE ABARTH'!X2 -> #N/A | M28: =SUM(C28:L28) -> #N/A | N28: =SUM(C28:H28) -> #N/A
B29: ='FASTBACK 1.0T'!A1 -> FASTBACK 1.0T | C29: ='FASTBACK 1.0T'!T2 -> #N/A | D29: ='FASTBACK 1.0T'!U2 -> #N/A | E29: ='FASTBACK 1.0T'!V2 -> #N/A | F29: ='FASTBACK 1.0T'!W2 -> #N/A | G29: ='FASTBACK 1.0T'!X2 -> #N/A | H29: ='FASTBACK 1.0T'!Y2 -> #N/A | I29: ='FASTBACK 1.0T'!Z2 -> #N/A | J29: ='FASTBACK 1.0T'!AA2 -> #N/A | ... L29: ='FASTBACK 1.0T'!AC2 -> #N/A | M29: =SUM(C29:L29) -> #N/A | N29: =SUM(C29:H29) -> #N/A
B30: ='FASTBACK 1.3T'!A1 -> FASTBACK ABARTH 1.3T | C30: ='FASTBACK 1.3T'!T2 -> #N/A | D30: ='FASTBACK 1.3T'!U2 -> #N/A | E30: ='FASTBACK 1.3T'!V2 -> #N/A | F30: ='FASTBACK 1.3T'!W2 -> #N/A | G30: ='FASTBACK 1.3T'!X2 -> #N/A | H30: ='FASTBACK 1.3T'!Y2 -> #N/A | I30: ='FASTBACK 1.3T'!Z2 -> #N/A | J30: ='FASTBACK 1.3T'!AA2 -> #N/A | ... L30: ='FASTBACK 1.3T'!AC2 -> #N/A | M30: =SUM(C30:L30) -> #N/A | N30: =SUM(C30:H30) -> #N/A
B31: ='TORO 1.8'!A1 -> TORO 1.8 | C31: ='TORO 1.8'!O2 -> 498 | D31: ='TORO 1.8'!P2 -> #N/A | E31: ='TORO 1.8'!Q2 -> #N/A | F31: ='TORO 1.8'!R2 -> #N/A | G31: ='TORO 1.8'!S2 -> #N/A | H31: ='TORO 1.8'!T2 -> #N/A | I31: ='TORO 1.8'!U2 -> #N/A | J31: ='TORO 1.8'!V2 -> #N/A | ... L31: ='TORO 1.8'!X2 -> #N/A | M31: =SUM(C31:L31) -> #N/A | N31: =SUM(C31:H31) -> #N/A
B32: ='TORO 2.4'!A1 -> TORO 2.4 | C32: ='TORO 2.4'!O2 -> 706 | D32: ='TORO 2.4'!P2 -> #N/A | E32: ='TORO 2.4'!Q2 -> #N/A | F32: ='TORO 2.4'!R2 -> #N/A | G32: ='TORO 2.4'!S2 -> #N/A | H32: ='TORO 2.4'!T2 -> #N/A | I32: ='TORO 2.4'!U2 -> #N/A | J32: ='TORO 2.4'!V2 -> #N/A | ... L32: ='TORO 2.4'!X2 -> #N/A | M32: =SUM(C32:L32) -> #N/A | N32: =SUM(C32:H32) -> #N/A
B33: ='TORO 1.3T'!A1 -> TORO 1.3T MY25 | C33: ='TORO 1.3T'!W2 -> #N/A | D33: ='TORO 1.3T'!X2 -> #N/A | E33: ='TORO 1.3T'!Y2 -> #N/A | F33: ='TORO 1.3T'!Z2 -> #N/A | G33: ='TORO 1.3T'!AA2 -> #N/A | H33: ='TORO 1.3T'!AB2 -> #N/A | I33: ='TORO 1.3T'!AC2 -> #N/A | J33: ='TORO 1.3T'!AD2 -> #N/A | ... L33: ='TORO 1.3T'!AF2 -> #N/A | M33: =SUM(C33:L33) -> #N/A | N33: =SUM(C33:H33) -> #N/A
B34: ='TORO 1.3T'!A13 -> TORO 1.3T MY26 | C34: ='TORO 1.3T'!W14 -> #N/A | D34: ='TORO 1.3T'!X14 -> #N/A | E34: ='TORO 1.3T'!Y14 -> #N/A | F34: ='TORO 1.3T'!Z14 -> #N/A | G34: ='TORO 1.3T'!AA14 -> #N/A | H34: ='TORO 1.3T'!AB14 -> #N/A | I34: ='TORO 1.3T'!AC14 -> #N/A | J34: ='TORO 1.3T'!AD14 -> #N/A | ... L34: ='TORO 1.3T'!AF14 -> #N/A | M34: =SUM(C34:L34) -> #N/A | N34: =SUM(C34:H34) -> #N/A
B35: TITANO MANUAL | C35: =TITANO!T2 -> #N/A | D35: =TITANO!U2 -> #N/A | E35: =TITANO!V2 -> #N/A | F35: =TITANO!W2 -> #N/A | G35: =TITANO!X2 -> #N/A | H35: =TITANO!Y2 -> #N/A | I35: =TITANO!Z2 -> #N/A | J35: =TITANO!AA2 -> #N/A | ... L35: =TITANO!AC2 -> #N/A | M35: =SUM(C35:L35) -> #N/A | N35: =SUM(C35:H35) -> #N/A
B36: TITANO AUTOMÁTICO | C36: =TITANO!T18 -> #N/A | D36: =TITANO!U18 -> #N/A | E36: =TITANO!V18 -> #N/A | F36: =TITANO!W18 -> #N/A | G36: =TITANO!X18 -> #N/A | H36: =TITANO!Y18 -> #N/A | I36: =TITANO!Z18 -> #N/A | J36: =TITANO!AA18 -> #N/A | ... L36: =TITANO!AC18 -> #N/A | M36: =SUM(C36:L36) -> #N/A | N36: =SUM(C36:H36) -> #N/A
B37: =TITANO!A33 -> TITANO 2.2D MT | C37: =TITANO!T34 -> #N/A | D37: =TITANO!U34 -> #N/A | E37: =TITANO!V34 -> #N/A | F37: =TITANO!W34 -> #N/A | G37: =TITANO!X34 -> #N/A | H37: =TITANO!Y34 -> #N/A | I37: =TITANO!Z34 -> #N/A | J37: =TITANO!AA34 -> #N/A | ... L37: =TITANO!AC34 -> #N/A | M37: =SUM(C37:L37) -> #N/A | N37: =SUM(C37:H37) -> #N/A
B38: =TITANO!A48 -> TITANO 2.2D AT | C38: =TITANO!T49 -> #N/A | D38: =TITANO!U49 -> #N/A | E38: =TITANO!V49 -> #N/A | F38: =TITANO!W49 -> #N/A | G38: =TITANO!X49 -> #N/A | H38: =TITANO!Y49 -> #N/A | I38: =TITANO!Z49 -> #N/A | J38: =TITANO!AA49 -> #N/A | ... L38: =TITANO!AC49 -> #N/A | M38: =SUM(C38:L38) -> #N/A | N38: =SUM(C38:H38) -> #N/A
B39: =B1 -> PREÇO PARA PUBLICAÇÃO - MAR.26 | N39: =SUM(C39:H39) -> 0
B40: a cada 20.000 Km ou 1 ano | N40: =SUM(C40:H40) -> 0
...

Sheet CRONOS 1.0
A1: CRONOS 1.0 até MY26 | E1: PLANO DE MANUTENÇÃO | T1: CUSTOS DE MANUTENÇÃO [R$] | AI1: Total
T2: =MROUND(SUM(T4:T12),1) -> #N/A | U2: =MROUND(SUM(U4:U12),1) -> #N/A | V2: =MROUND(SUM(V4:V12),1) -> #N/A | W2: =MROUND(SUM(W4:W12),1) -> #N/A | X2: =MROUND(SUM(X4:X12),1) -> #N/A | Y2: =MROUND(SUM(Y4:Y12),1) -> #N/A | Z2: =MROUND(SUM(Z4:Z12),1) -> #N/A | AA2: =MROUND(SUM(AA4:AA12),1) -> #N/A | ... AH2: =MROUND(SUM(AH4:AH12),1) -> #N/A | AI2: =SUM(T2:AH2) -> #N/A
A3: Nº | B3: ITENS DE SUBSTITUIÇÃO OBRIGATÓRIA | C3: PN | D3: P. PUB. | E3: 1a | F3: 2a | G3: 3a | H3: 4a | I3: 5a | J3: 6a | K3: 7a | L3: 8a | M3: 9a | N3: 10a | O3: 11 | P3: 12 | Q3: 13 | R3: 14 | S3: 15 | T3: 10000 | U3: 20000 | V3: 30000 | W3: 40000 | X3: 50000 | Y3: 60000 | Z3: 70000 | AA3: 80000 | AB3: 90000 | AC3: 100000 | AD3: =AC3+10000 -> 110000 | AE3: =AD3+10000 -> 120000 | AF3: =AE3+10000 -> 130000 | AG3: =AF3+10000 -> 140000 | AH3: =AG3+10000 -> 150000 | AI3: % 100 | AJ3: TTL 100
A4: 1 | B4: Filtro de Óleo do Motor | C4: 7094709 | D4: =VLOOKUP(C4,'[1]PREÇO ATUAL'!$A:$D,4,0) -> 79.9 | E4: 1 | F4: 1 | G4: 1 | H4: 1 | I4: 1 | J4: 1 | K4: 1 | L4: 1 | M4: 1 | N4: 1 | O4: 1 | P4: 1 | Q4: 1 | R4: 1 | S4: 1 | T4: =$D4*E4 -> 79.9 | U4: =$D4*F4 -> 79.9 | V4: =$D4*G4 -> 79.9 | W4: =$D4*H4 -> 79.9 | X4: =$D4*I4 -> 79.9 | Y4: =$D4*J4 -> 79.9 | Z4: =$D4*K4 -> 79.9 | AA4: =$D4*L4 -> 79.9 | ... AH4: =$D4*S4 -> 79.9 | AI4: =AJ4/$AI$2 -> #N/A | AJ4: =SUM(T4:AH4) -> 1198.5
A5: 2 | B5: Filtro de Combustível | C5: 52162685 | D5: =VLOOKUP(C5,'[1]PREÇO ATUAL'!$A:$D,4,0) -> 35.9 | F5: 1 | H5: 1 | J5: 1 | L5: 1 | N5: 1 | P5: 1 | R5: 1 | T5: =$D5*E5 -> 0 | U5: =$D5*F5 -> 35.9 | V5: =$D5*G5 -> 0 | W5: =$D5*H5 -> 35.9 | X5: =$D5*I5 -> 0 | Y5: =$D5*J5 -> 35.9 | Z5: =$D5*K5 -> 0 | AA5: =$D5*L5 -> 35.9 | ... AH5: =$D5*S5 -> 0 | AI5: =AJ5/$AI$2 -> #N/A | AJ5: =SUM(T5:AH5) -> 251.3
A6: 3 | B6: Filtro de Ar | C6: 52046268 | D6: =VLOOKUP(C6,'[1]PREÇO ATUAL'!$A:$D,4,0) -> 89.9 | F6: 1 | H6: 1 | J6: 1 | L6: 1 | N6: 1 | P6: 1 | R6: 1 | T6: =$D6*E6 -> 0 | U6: =$D6*F6 -> 89.9 | V6: =$D6*G6 -> 0 | W6: =$D6*H6 -> 89.9 | X6: =$D6*I6 -> 0 | Y6: =$D6*J6 -> 89.9 | Z6: =$D6*K6 -> 0 | AA6: =$D6*L6 -> 89.9 | ... AH6: =$D6*S6 -> 0 | AI6: =AJ6/$AI$2 -> #N/A | AJ6: =SUM(T6:AH6) -> 629.3
A7: 4 | B7: Velas de Ignição | C7: 55267995 | D7: =VLOOKUP(C7,'[1]PREÇO ATUAL'!$A:$D,4,0) -> 175.9 | H7: 3 | L7: 3 | P7: 4 | T7: =$D7*E7 -> 0 | U7: =$D7*F7 -> 0 | V7: =$D7*G7 -> 0 | W7: =$D7*H7 -> 527.7 | X7: =$D7*I7 -> 0 | Y7: =$D7*J7 -> 0 | Z7: =$D7*K7 -> 0 | AA7: =$D7*L7 -> 527.7 | ... AH7: =$D7*S7 -> 0 | AI7: =AJ7/$AI$2 -> #N/A | AJ7: =SUM(T7:AH7) -> 1759
A8: 5 | B8: Correia dos Órgãos Auxiliares | C8: 55267966 | D8: =VLOOKUP(C8,'[1]PREÇO ATUAL'!$A:$D,4,0) -> 143.23 | J8: 1 | P8: 1 | T8: =$D8*E8 -> 0 | U8: =$D8*F8 -> 0 | V8: =$D8*G8 -> 0 | W8: =$D8*H8 -> 0 | X8: =$D8*I8 -> 0 | Y8: =$D8*J8 -> 143.23 | Z8: =$D8*K8 -> 0 | AA8: =$D8*L8 -> 0 | ... AH8: =$D8*S8 -> 0 | AI8: =AJ8/$AI$2 -> #N/A | AJ8: =SUM(T8:AH8) -> 286.46
A9: 6 | B9: Óleo da caixa de cambio mecanica - SAE 75W – API GL4 | C9: 7095576 | D9: =VLOOKUP(C9,'[1]PREÇO ATUAL'!$A:$D,4,0) -> 165.97812 | P9: 2 | T9: =$D9*E9 -> 0 | U9: =$D9*F9 -> 0 | V9: =$D9*G9 -> 0 | W9: =$D9*H9 -> 0 | X9: =$D9*I9 -> 0 | Y9: =$D9*J9 -> 0 | Z9: =$D9*K9 -> 0 | AA9: =$D9*L9 -> 0 | ... AH9: =$D9*S9 -> 0 | AI9: =AJ9/$AI$2 -> #N/A | AJ9: =SUM(T9:AH9) -> 331.95624
A10: 7 | B10: MOPAR BRAKE FLUID DOT 4 - A cada 2 anos | C10: K04549625LA_F | D10: =VLOOKUP(C10,'[1]PREÇO ATUAL'!$A:$D,4,0) -> 33.622493 | T10: =$D10*E10 -> 0 | U10: =$D10*F10 -> 0 | V10: =$D10*G10 -> 0 | W10: =$D10*H10 -> 0 | X10: =$D10*I10 -> 0 | Y10: =$D10*J10 -> 0 | Z10: =$D10*K10 -> 0 | AA10: =$D10*L10 -> 0 | ... AH10: =$D10*S10 -> 0 | AI10: =AJ10/$AI$2 -> #N/A | AJ10: =SUM(T10:AH10) -> 0
A11: 8 | B11: MOPAR MAXPRO SYNTHETIC 0W20 (SP/GF-6A) | C11: K68218951LA_F | D11: =VLOOKUP(C11,'[1]PREÇO ATUAL'!$A:$D,4,0) -> 81.26 | E11: 2.54 | F11: 2.54 | G11: 2.54 | H11: 2.54 | I11: 2.54 | J11: 2.54 | K11: 2.54 | L11: 2.54 | M11: 2.54 | N11: 2.54 | O11: 2.54 | P11: 2.54 | Q11: 2.54 | R11: 2.54 | S11: 2.54 | T11: =$D11*E11 -> 206.4004 | U11: =$D11*F11 -> 206.4004 | V11: =$D11*G11 -> 206.4004 | W11: =$D11*H11 -> 206.4004 | X11: =$D11*I11 -> 206.4004 | Y11: =$D11*J11 -> 206.4004 | Z11: =$D11*K11 -> 206.4004 | AA11: =$D11*L11 -> 206.4004 | ... AH11: =$D11*S11 -> 206.4004 | AI11: =AJ11/$AI$2 -> #N/A | AJ11: =SUM(T11:AH11) -> 3096.006
A12: 9 | B12: Tempo Padrão de Mão-De-Obra [horas] | C12: MO FIAT | D12: =VLOOKUP(C12,'[1]PREÇO ATUAL'!$A:$D,4,0) -> #N/A | E12: 0.85 | F12: 1.2 | G12: 0.9 | H12: 2.15 | I12: 1 | J12: 1.45 | K12: 0.85 | L12: 2.15 | M12: 0.9 | N12: 1.35 | O12: 0.85 | P12: 1.5 | Q12: 0.85 | R12: 1.2 | S12: 1.05 | T12: =D12*E12 -> #N/A | U12: =$D12*F12 -> #N/A | V12: =$D12*G12 -> #N/A | W12: =$D12*H12 -> #N/A | X12: =$D12*I12 -> #N/A | Y12: =$D12*J12 -> #N/A | Z12: =$D12*K12 -> #N/A | AA12: =$D12*L12 -> #N/A | AB12: =$D12*M12 -> #N/A | ... AH12: =$D12*S12 -> #N/A | AI12: =AJ12/$AI$2 -> #N/A | AJ12: =SUM(T12:AH12) -> #N/A
A14: CRONOS 1.0 MY27 | E14: PLANO DE MANUTENÇÃO | T14: CUSTOS DE MANUTENÇÃO [R$] | AI14: Total
T15: =MROUND(SUM(T17:T26),1) -> #N/A | U15: =MROUND(SUM(U17:U26),1) -> #N/A | V15: =MROUND(SUM(V17:V26),1) -> #N/A | W15: =MROUND(SUM(W17:W26),1) -> #N/A | X15: =MROUND(SUM(X17:X26),1) -> #N/A | Y15: =MROUND(SUM(Y17:Y26),1) -> #N/A | Z15: =MROUND(SUM(Z17:Z26),1) -> #N/A | AA15: =MROUND(SUM(AA17:AA26),1) -> #N/A | ... AH15: =MROUND(SUM(AH17:AH26),1) -> #N/A | AI15: =SUM(T15:AH15) -> #N/A
A16: Nº | B16: ITENS DE SUBSTITUIÇÃO OBRIGATÓRIA | C16: PN | D16: P. PUB. | E16: 1a | F16: 2a | G16: 3a | H16: 4a | I16: 5a | J16: 6a | K16: 7a | L16: 8a | M16: 9a | N16: 10a | O16: 11 | P16: 12 | Q16: 13 | R16: 14 | S16: 15 | T16: 10000 | U16: 20000 | V16: 30000 | W16: 40000 | X16: 50000 | Y16: 60000 | Z16: 70000 | AA16: 80000 | AB16: 90000 | AC16: 100000 | AD16: =AC16+10000 -> 110000 | AE16: =AD16+10000 -> 120000 | AF16: =AE16+10000 -> 130000 | AG16: =AF16+10000 -> 140000 | AH16: =AG16+10000 -> 150000 | AI16: % 100 | AJ16: TTL 100
A17: 1 | B17: Filtro de óleo do motor | C17: 7094709 | D17: =VLOOKUP(C17,'[1]PREÇO ATUAL'!$A:$D,4,0) -> 79.9 | E17: 1 | F17: 1 | G17: 1 | H17: 1 | I17: 1 | J17: 1 | K17: 1 | L17: 1 | M17: 1 | N17: 1 | O17: 1 | P17: 1 | Q17: 1 | R17: 1 | S17: 1 | T17: =$D17*E17 -> 79.9 | U17: =$D17*F17 -> 79.9 | V17: =$D17*G17 -> 79.9 | W17: =$D17*H17 -> 79.9 | X17: =$D17*I17 -> 79.9 | Y17: =$D17*J17 -> 79.9 | Z17: =$D17*K17 -> 79.9 | AA17: =$D17*L17 -> 79.9 | ... AH17: =$D17*S17 -> 79.9 | AI17: =AJ17/$AI$2 -> #N/A | AJ17: =SUM(T17:AH17) -> 1198.5
A18: 2 | B18: Filtro de Combustível | C18: 52162685 | D18: =VLOOKUP(C18,'[1]PREÇO ATUAL'!$A:$D,4,0) -> 35.9 | F18: 1 | H18: 1 | J18: 1 | L18: 1 | N18: 1 | P18: 1 | R18: 1 | T18: =$D18*E18 -> 0 | U18: =$D18*F18 -> 35.9 | V18: =$D18*G18 -> 0 | W18: =$D18*H18 -> 35.9 | X18: =$D18*I18 -> 0 | Y18: =$D18*J18 -> 35.9 | Z18: =$D18*K18 -> 0 | AA18: =$D18*L18 -> 35.9 | ... AH18: =$D18*S18 -> 0 | AI18: =AJ18/$AI$2 -> #N/A | AJ18: =SUM(T18:AH18) -> 251.3
A19: 3 | B19: Elemento do filtro de ar do motor | C19: 52046268 | D19: =VLOOKUP(C19,'[1]PREÇO ATUAL'!$A:$D,4,0) -> 89.9 | F19: 1 | H19: 1 | J19: 1 | L19: 1 | N19: 1 | P19: 1 | R19: 1 | T19: =$D19*E19 -> 0 | U19: =$D19*F19 -> 89.9 | V19: =$D19*G19 -> 0 | W19: =$D19*H19 -> 89.9 | X19: =$D19*I19 -> 0 | Y19: =$D19*J19 -> 89.9 | Z19: =$D19*K19 -> 0 | AA19: =$D19*L19 -> 89.9 | ... AH19: =$D19*S19 -> 0 | AI19: =AJ19/$AI$2 -> #N/A | AJ19: =SUM(T19:AH19) -> 629.3
A20: 4 | B20: Filtro de ar limpo do canister | C20: 7096883 | D20: =VLOOKUP(C20,'[1]PREÇO ATUAL'!$A:$D,4,0) -> 199.05 | E20: 1 | F20: 1 | G20: 1 | H20: 1 | I20: 1 | J20: 1 | K20: 1 | L20: 1 | M20: 1 | N20: 1 | O20: 1 | P20: 1 | Q20: 1 | R20: 1 | S20: 1 | T20: =$D20*E20 -> 199.05 | U20: =$D20*F20 -> 199.05 | V20: =$D20*G20 -> 199.05 | W20: =$D20*H20 -> 199.05 | X20: =$D20*I20 -> 199.05 | Y20: =$D20*J20 -> 199.05 | Z20: =$D20*K20 -> 199.05 | AA20: =$D20*L20 -> 199.05 | ... AH20: =$D20*S20 -> 199.05 | AI20: =AJ20/$AI$2 -> #N/A | AJ20: =SUM(T20:AH20) -> 2985.75
A21: 5 | B21: Velas de ignição do motor (a cada 40.000 km, independente do tempo) | C21: 55267995 | D21: =VLOOKUP(C21,'[1]PREÇO ATUAL'!$A:$D,4,0) -> 175.9 | H21: 3 | L21: 3 | P21: 3 | T21: =$D21*E21 -> 0 | U21: =$D21*F21 -> 0 | V21: =$D21*G21 -> 0 | W21: =$D21*H21 -> 527.7 | X21: =$D21*I21 -> 0 | Y21: =$D21*J21 -> 0 | Z21: =$D21*K21 -> 0 | AA21: =$D21*L21 -> 527.7 | ... AH21: =$D21*S21 -> 0 | AI21: =AJ21/$AI$2 -> #N/A | AJ21: =SUM(T21:AH21) -> 1583.1
A22: 6 | B22: Correia dos órgão auxiliares (a cada 60.000 km ou 4 anos, o que ocorrer primeiro) | C22: 55267966 | D22: =VLOOKUP(C22,'[1]PREÇO ATUAL'!$A:$D,4,0) -> 143.23 | T22: =$D22*E22 -> 0 | U22: =$D22*F22 -> 0 | V22: =$D22*G22 -> 0 | W22: =$D22*H22 -> 0 | X22: =$D22*I22 -> 0 | Y22: =$D22*J22 -> 0 | Z22: =$D22*K22 -> 0 | AA22: =$D22*L22 -> 0 | ... AH22: =$D22*S22 -> 0 | AI22: =AJ22/$AI$2 -> #N/A | AJ22: =SUM(T22:AH22) -> 0
A23: 7 | B23: Substituição do óleo da caixa de cambio mecanica | C23: 7095576 | D23: =VLOOKUP(C23,'[1]PREÇO ATUAL'!$A:$D,4,0) -> 165.97812 | T23: =$D23*E23 -> 0 | U23: =$D23*F23 -> 0 | V23: =$D23*G23 -> 0 | W23: =$D23*H23 -> 0 | X23: =$D23*I23 -> 0 | Y23: =$D23*J23 -> 0 | Z23: =$D23*K23 -> 0 | AA23: =$D23*L23 -> 0 | ... AH23: =$D23*S23 -> 0 | AI23: =AJ23/$AI$2 -> #N/A | AJ23: =SUM(T23:AH23) -> 0
A24: 8 | B24: Fluído de freio (a cada 40.000 km ou 2 anos, ou que ocurrer primeiro) | C24: K04549625LA_F | D24: =VLOOKUP(C24,'[1]PREÇO ATUAL'!$A:$D,4,0) -> 33.622493 | T24: =$D24*E24 -> 0 | U24: =$D24*F24 -> 0 | V24: =$D24*G24 -> 0 | W24: =$D24*H24 -> 0 | X24: =$D24*I24 -> 0 | Y24: =$D24*J24 -> 0 | Z24: =$D24*K24 -> 0 | AA24: =$D24*L24 -> 0 | ... AH24: =$D24*S24 -> 0 | AI24: =AJ24/$AI$2 -> #N/A | AJ24: =SUM(T24:AH24) -> 0
A25: 9 | B25: Óleo do motor - MOPAR MAXPRO SYNTHETIC 0W20 (SP/GF-6A) | C25: K68218951LA_F | D25: =VLOOKUP(C25,'[1]PREÇO ATUAL'!$A:$D,4,0) -> 81.26 | E25: 2.54 | F25: 2.54 | G25: 2.54 | H25: 2.54 | I25: 2.54 | J25: 2.54 | K25: 2.54 | L25: 2.54 | M25: 2.54 | N25: 2.54 | O25: 2.54 | P25: 2.54 | Q25: 2.54 | R25: 2.54 | S25: 2.54 | T25: =D25*E25 -> 206.4004 | U25: =$D25*F25 -> 206.4004 | V25: =$D25*G25 -> 206.4004 | W25: =$D25*H25 -> 206.4004 | X25: =$D25*I25 -> 206.4004 | Y25: =$D25*J25 -> 206.4004 | Z25: =$D25*K25 -> 206.4004 | AA25: =$D25*L25 -> 206.4004 | AB25: =$D25*M25 -> 206.4004 | ... AH25: =$D25*S25 -> 206.4004 | AI25: =AJ25/$AI$2 -> #N/A | AJ25: =SUM(T25:AH25) -> 3096.006
A26: 10 | B26: Tempo Padrão de Mão-De-Obra [horas] | C26: MO FIAT | D26: =VLOOKUP(C26,'[1]PREÇO ATUAL'!$A:$D,4,0) -> #N/A | E26: 1.05 | F26: 1.4 | G26: 1.1 | H26: 2.4 | I26: 1.2 | J26: 1.65 | K26: 1.05 | L26: 2.4 | M26: 1.1 | N26: 1.55 | O26: 1.05 | P26: 1.7 | Q26: 1.05 | R26: 1.4 | S26: 1.25 | T26: =$D26*E26 -> #N/A | U26: =$D26*F26 -> #N/A | V26: =$D26*G26 -> #N/A | W26: =$D26*H26 -> #N/A | X26: =$D26*I26 -> #N/A | Y26: =$D26*J26 -> #N/A | Z26: =$D26*K26 -> #N/A | AA26: =$D26*L26 -> #N/A | ... AH26: =$D26*S26 -> #N/A | AI26: =AJ26/$AI$2 -> #N/A | AJ26: =SUM(T26:AH26) -> #N/A

Sheet CRONOS 1.3
A1: CRONOS 1.3 até MY26 | E1: PLANO DE MANUTENÇÃO | T1: CUSTOS DE MANUTENÇÃO [R$] | AI1: Total
T2: =MROUND(SUM(T4:T12),1) -> #N/A | U2: =MROUND(SUM(U4:U12),1) -> #N/A | V2: =MROUND(SUM(V4:V12),1) -> #N/A | W2: =MROUND(SUM(W4:W12),1) -> #N/A | X2: =MROUND(SUM(X4:X12),1) -> #N/A | Y2: =MROUND(SUM(Y4:Y12),1) -> #N/A | Z2: =MROUND(SUM(Z4:Z12),1) -> #N/A | AA2: =MROUND(SUM(AA4:AA12),1) -> #N/A | ... AH2: =MROUND(SUM(AH4:AH12),1) -> #N/A | AI2: =SUM(T2:AH2) -> #N/A
A3: Nº | B3: ITENS DE SUBSTITUIÇÃO OBRIGATÓRIA | C3: PN | D3: P. PUB. | E3: 1a | F3: 2a | G3: 3a | H3: 4a | I3: 5a | J3: 6a | K3: 7a | L3: 8a | M3: 9a | N3: 10a | O3: 11 | P3: 12 | Q3: 13 | R3: 14 | S3: 15 | T3: 10000 | U3: 20000 | V3: 30000 | W3: 40000 | X3: 50000 | Y3: 60000 | Z3: 70000 | AA3: 80000 | AB3: 90000 | AC3: 100000 | AD3: =AC3+10000 -> 110000 | AE3: =AD3+10000 -> 120000 | AF3: =AE3+10000 -> 130000 | AG3: =AF3+10000 -> 140000 | AH3: =AG3+10000 -> 150000 | AI3: % 100 | AJ3: TTL 100
A4: 1 | B4: Filtro de Óleo do Motor | C4: 7094709 | D4: =VLOOKUP(C4,'[1]PREÇO ATUAL'!$A:$D,4,0) -> 79.9 | E4: 1 | F4: 1 | G4: 1 | H4: 1 | I4: 1 | J4: 1 | K4: 1 | L4: 1 | M4: 1 | N4: 1 | O4: 1 | P4: 1 | Q4: 1 | R4: 1 | S4: 1 | T4: =$D4*E4 -> 79.9 | U4: =$D4*F4 -> 79.9 | V4: =$D4*G4 -> 79.9 | W4: =$D4*H4 -> 79.9 | X4: =$D4*I4 -> 79.9 | Y4: =$D4*J4 -> 79.9 | Z4: =$D4*K4 -> 79.9 | AA4: =$D4*L4 -> 79.9 | ... AH4: =$D4*S4 -> 79.9 | AI4: =AJ4/$AI$2 -> #N/A | AJ4: =SUM(T4:AH4) -> 1198.5
A5: 2 | B5: Filtro de Combustível | C5: 52162685 | D5: =VLOOKUP(C5,'[1]PREÇO ATUAL'!$A:$D,4,0) -> 35.9 | F5: 1 | H5: 1 | J5: 1 | L5: 1 | N5: 1 | P5: 1 | R5: 1 | T5: =$D5*E5 -> 0 | U5: =$D5*F5 -> 35.9 | V5: =$D5*G5 -> 0 | W5: =$D5*H5 -> 35.9 | X5: =$D5*I5 -> 0 | Y5: =$D5*J5 -> 35.9 | Z5: =$D5*K5 -> 0 | AA5: =$D5*L5 -> 35.9 | ... AH5: =$D5*S5 -> 0 | AI5: =AJ5/$AI$2 -> #N/A | AJ5: =SUM(T5:AH5) -> 251.3
A6: 3 | B6: Filtro de Ar | C6: 52046268 | D6: =VLOOKUP(C6,'[1]PREÇO ATUAL'!$A:$D,4,0) -> 89.9 | F6: 1 | H6: 1 | J6: 1 | L6: 1 | N6: 1 | P6: 1 | R6: 1 | T6: =$D6*E6 -> 0 | U6: =$D6*F6 -> 89.9 | V6: =$D6*G6 -> 0 | W6: =$D6*H6 -> 89.9 | X6: =$D6*I6 -> 0 | Y6: =$D6*J6 -> 89.9 | Z6: =$D6*K6 -> 0 | AA6: =$D6*L6 -> 89.9 | ... AH6: =$D6*S6 -> 0 | AI6: =AJ6/$AI$2 -> #N/A | AJ6: =SUM(T6:AH6) -> 629.3
A7: 4 | B7: Velas de Ignição | C7: 55267995 | D7: =VLOOKUP(C7,'[1]PREÇO ATUAL'!$A:$D,4,0) -> 175.9 | H7: 4 | L7: 4 | P7: 4 | T7: =$D7*E7 -> 0 | U7: =$D7*F7 -> 0 | V7: =$D7*G7 -> 0 | W7: =$D7*H7 -> 703.6 | X7: =$D7*I7 -> 0 | Y7: =$D7*J7 -> 0 | Z7: =$D7*K7 -> 0 | AA7: =$D7*L7 -> 703.6 | ... AH7: =$D7*S7 -> 0 | AI7: =AJ7/$AI$2 -> #N/A | AJ7: =SUM(T7:AH7) -> 2110.8
A8: 5 | B8: Correia dos Órgãos Auxiliares | C8: 55267966 | D8: =VLOOKUP(C8,'[1]PREÇO ATUAL'!$A:$D,4,0) -> 143.23 | J8: 1 | P8: 1 | T8: =$D8*E8 -> 0 | U8: =$D8*F8 -> 0 | V8: =$D8*G8 -> 0 | W8: =$D8*H8 -> 0 | X8: =$D8*I8 -> 0 | Y8: =$D8*J8 -> 143.23 | Z8: =$D8*K8 -> 0 | AA8: =$D8*L8 -> 0 | ... AH8: =$D8*S8 -> 0 | AI8: =AJ8/$AI$2 -> #N/A | AJ8: =SUM(T8:AH8) -> 286.46
A9: 6 | B9: Óleo da caixa de cambio mecanica - SAE 75W – API GL4 | C9: 7095576 | D9: =VLOOKUP(C9,'[1]PREÇO ATUAL'!$A:$D,4,0) -> 165.97812 | P9: 2 | T9: =$D9*E9 -> 0 | U9: =$D9*F9 -> 0 | V9: =$D9*G9 -> 0 | W9: =$D9*H9 -> 0 | X9: =$D9*I9 -> 0 | Y9: =$D9*J9 -> 0 | Z9: =$D9*K9 -> 0 | AA9: =$D9*L9 -> 0 | ... AH9: =$D9*S9 -> 0 | AI9: =AJ9/$AI$2 -> #N/A | AJ9: =SUM(T9:AH9) -> 331.95624
A10: 7 | B10: MOPAR BRAKE FLUID DOT 4 - A cada 2 anos | C10: K04549625LA_F | D10: =VLOOKUP(C10,'[1]PREÇO ATUAL'!$A:$D,4,0) -> 33.622493 | T10: =$D10*E10 -> 0 | U10: =$D10*F10 -> 0 | V10: =$D10*G10 -> 0 | W10: =$D10*H10 -> 0 | X10: =$D10*I10 -> 0 | Y10: =$D10*J10 -> 0 | Z10: =$D10*K10 -> 0 | AA10: =$D10*L10 -> 0 | ... AH10: =$D10*S10 -> 0 | AI10: =AJ10/$AI$2 -> #N/A | AJ10: =SUM(T10:AH10) -> 0
A11: 8 | B11: MOPAR MAXPRO SYNTHETIC 0W20 (SP/GF-6A) | C11: K68218951LA_F | D11: =VLOOKUP(C11,'[1]PREÇO ATUAL'!$A:$D,4,0) -> 81.26 | E11: 3.36 | F11: 3.36 | G11: 3.36 | H11: 3.36 | I11: 3.36 | J11: 3.36 | K11: 3.36 | L11: 3.36 | M11: 3.36 | N11: 3.36 | O11: 3.36 | P11: 3.36 | Q11: 3.36 | R11: 3.36 | S11: 3.36 | T11: =$D11*E11 -> 273.0336 | U11: =$D11*F11 -> 273.0336 | V11: =$D11*G11 -> 273.0336 | W11: =$D11*H11 -> 273.0336 | X11: =$D11*I11 -> 273.0336 | Y11: =$D11*J11 -> 273.0336 | Z11: =$D11*K11 -> 273.0336 | AA11: =$D11*L11 -> 273.0336 | ... AH11: =$D11*S11 -> 273.0336 | AI11: =AJ11/$AI$2 -> #N/A | AJ11: =SUM(T11:AH11) -> 4095.504
A12: 9 | B12: Tempo Padrão de Mão-De-Obra [horas] | C12: MO FIAT | D12: =VLOOKUP(C12,'[1]PREÇO ATUAL'!$A:$D,4,0) -> #N/A | E12: 0.85 | F12: 1.2 | G12: 0.9 | H12: 2.15 | I12: 1 | J12: 1.45 | K12: 0.85 | L12: 2.15 | M12: 0.9 | N12: 1.35 | O12: 0.85 | P12: 1.5 | Q12: 0.85 | R12: 1.2 | S12: 1.05 | T12: =D12*E12 -> #N/A | U12: =$D12*F12 -> #N/A | V12: =$D12*G12 -> #N/A | W12: =$D12*H12 -> #N/A | X12: =$D12*I12 -> #N/A | Y12: =$D12*J12 -> #N/A | Z12: =$D12*K12 -> #N/A | AA12: =$D12*L12 -> #N/A | AB12: =$D12*M12 -> #N/A | ... AH12: =$D12*S12 -> #N/A | AI12: =AJ12/$AI$2 -> #N/A | AJ12: =SUM(T12:AH12) -> #N/A
A14: CRONOS 1.3 MY27 MT | E14: PLANO DE MANUTENÇÃO | T14: CUSTOS DE MANUTENÇÃO [R$] | AI14: Total
T15: =MROUND(SUM(T17:T26),1) -> #N/A | U15: =MROUND(SUM(U17:U26),1) -> #N/A | V15: =MROUND(SUM(V17:V26),1) -> #N/A | W15: =MROUND(SUM(W17:W26),1) -> #N/A | X15: =MROUND(SUM(X17:X26),1) -> #N/A | Y15: =MROUND(SUM(Y17:Y26),1) -> #N/A | Z15: =MROUND(SUM(Z17:Z26),1) -> #N/A | AA15: =MROUND(SUM(AA17:AA26),1) -> #N/A | ... AH15: =MROUND(SUM(AH17:AH26),1) -> #N/A | AI15: =SUM(T15:AH15) -> #N/A
A16: Nº | B16: ITENS DE SUBSTITUIÇÃO OBRIGATÓRIA | C16: PN | D16: P. PUB. | E16: 1a | F16: 2a | G16: 3a | H16: 4a | I16: 5a | J16: 6a | K16: 7a | L16: 8a | M16: 9a | N16: 10a | O16: 11 | P16: 12 | Q16: 13 | R16: 14 | S16: 15 | T16: 10000 | U16: 20000 | V16: 30000 | W16: 40000 | X16: 50000 | Y16: 60000 | Z16: 70000 | AA16: 80000 | AB16: 90000 | AC16: 100000 | AD16: =AC16+10000 -> 110000 | AE16: =AD16+10000 -> 120000 | AF16: =AE16+10000 -> 130000 | AG16: =AF16+10000 -> 140000 | AH16: =AG16+10000 -> 150000 | AI16: % 100 | AJ16: TTL 100
A17: 1 | B17: Filtro de óleo do motor | C17: 7094709 | D17: =VLOOKUP(C17,'[1]PREÇO ATUAL'!$A:$D,4,0) -> 79.9 | E17: 1 | F17: 1 | G17: 1 | H17: 1 | I17: 1 | J17: 1 | K17: 1 | L17: 1 | M17: 1 | N17: 1 | O17: 1 | P17: 1 | Q17: 1 | R17: 1 | S17: 1 | T17: =$D17*E17 -> 79.9 | U17: =$D17*F17 -> 79.9 | V17: =$D17*G17 -> 79.9 | W17: =$D17*H17 -> 79.9 | X17: =$D17*I17 -> 79.9 | Y17: =$D17*J17 -> 79.9 | Z17: =$D17*K17 -> 79.9 | AA17: =$D17*L17 -> 79.9 | ... AH17: =$D17*S17 -> 79.9 | AI17: =AJ17/$AI$2 -> #N/A | AJ17: =SUM(T17:AH17) -> 1198.5
A18: 2 | B18: Filtro de Combustível | C18: 52162685 | D18: =VLOOKUP(C18,'[1]PREÇO ATUAL'!$A:$D,4,0) -> 35.9 | F18: 1 | H18: 1 | J18: 1 | L18: 1 | N18: 1 | P18: 1 | R18: 1 | T18: =$D18*E18 -> 0 | U18: =$D18*F18 -> 35.9 | V18: =$D18*G18 -> 0 | W18: =$D18*H18 -> 35.9 | X18: =$D18*I18 -> 0 | Y18: =$D18*J18 -> 35.9 | Z18: =$D18*K18 -> 0 | AA18: =$D18*L18 -> 35.9 | ... AH18: =$D18*S18 -> 0 | AI18: =AJ18/$AI$2 -> #N/A | AJ18: =SUM(T18:AH18) -> 251.3
A19: 3 | B19: Elemento do filtro de ar do motor | C19: 52046268 | D19: =VLOOKUP(C19,'[1]PREÇO ATUAL'!$A:$D,4,0) -> 89.9 | F19: 1 | H19: 1 | J19: 1 | L19: 1 | N19: 1 | P19: 1 | R19: 1 | T19: =$D19*E19 -> 0 | U19: =$D19*F19 -> 89.9 | V19: =$D19*G19 -> 0 | W19: =$D19*H19 -> 89.9 | X19: =$D19*I19 -> 0 | Y19: =$D19*J19 -> 89.9 | Z19: =$D19*K19 -> 0 | AA19: =$D19*L19 -> 89.9 | ... AH19: =$D19*S19 -> 0 | AI19: =AJ19/$AI$2 -> #N/A | AJ19: =SUM(T19:AH19) -> 629.3
A20: 4 | B20: Filtro de ar limpo do canister | C20: 7096883 | D20: =VLOOKUP(C20,'[1]PREÇO ATUAL'!$A:$D,4,0) -> 199.05 | E20: 1 | F20: 1 | G20: 1 | H20: 1 | I20: 1 | J20: 1 | K20: 1 | L20: 1 | M20: 1 | N20: 1 | O20: 1 | P20: 1 | Q20: 1 | R20: 1 | S20: 1 | T20: =$D20*E20 -> 199.05 | U20: =$D20*F20 -> 199.05 | V20: =$D20*G20 -> 199.05 | W20: =$D20*H20 -> 199.05 | X20: =$D20*I20 -> 199.05 | Y20: =$D20*J20 -> 199.05 | Z20: =$D20*K20 -> 199.05 | AA20: =$D20*L20 -> 199.05 | ... AH20: =$D20*S20 -> 199.05 | AI20: =AJ20/$AI$2 -> #N/A | AJ20: =SUM(T20:AH20) -> 2985.75
A21: 5 | B21: Velas de ignição do motor (a cada 40.000 km, independente do tempo) | C21: 55267995 | D21: =VLOOKUP(C21,'[1]PREÇO ATUAL'!$A:$D,4,0) -> 175.9 | H21: 4 | L21: 4 | P21: 4 | T21: =$D21*E21 -> 0 | U21: =$D21*F21 -> 0 | V21: =$D21*G21 -> 0 | W21: =$D21*H21 -> 703.6 | X21: =$D21*I21 -> 0 | Y21: =$D21*J21 -> 0 | Z21: =$D21*K21 -> 0 | AA21: =$D21*L21 -> 703.6 | ... AH21: =$D21*S21 -> 0 | AI21: =AJ21/$AI$2 -> #N/A | AJ21: =SUM(T21:AH21) -> 2110.8
A22: 6 | B22: Correia dos órgão auxiliares (a cada 60.000 km ou 4 anos, o que ocorrer primeiro) | C22: 55267966 | D22: =VLOOKUP(C22,'[1]PREÇO ATUAL'!$A:$D,4,0) -> 143.23 | T22: =$D22*E22 -> 0 | U22: =$D22*F22 -> 0 | V22: =$D22*G22 -> 0 | W22: =$D22*H22 -> 0 | X22: =$D22*I22 -> 0 | Y22: =$D22*J22 -> 0 | Z22: =$D22*K22 -> 0 | AA22: =$D22*L22 -> 0 | ... AH22: =$D22*S22 -> 0 | AI22: =AJ22/$AI$2 -> #N/A | AJ22: =SUM(T22:AH22) -> 0
A23: 7 | B23: Substituição do óleo da caixa de cambio mecanica | C23: 7095576 | D23: =VLOOKUP(C23,'[1]PREÇO ATUAL'!$A:$D,4,0) -> 165.97812 | T23: =$D23*E23 -> 0 | U23: =$D23*F23 -> 0 | V23: =$D23*G23 -> 0 | W23: =$D23*H23 -> 0 | X23: =$D23*I23 -> 0 | Y23: =$D23*J23 -> 0 | Z23: =$D23*K23 -> 0 | AA23: =$D23*L23 -> 0 | ... AH23: =$D23*S23 -> 0 | AI23: =AJ23/$AI$2 -> #N/A | AJ23: =SUM(T23:AH23) -> 0
A24: 8 | B24: Fluído de freio (a cada 40.000 km ou 2 anos, ou que ocurrer primeiro) | C24: K04549625LA_F | D24: =VLOOKUP(C24,'[1]PREÇO ATUAL'!$A:$D,4,0) -> 33.622493 | T24: =$D24*E24 -> 0 | U24: =$D24*F24 -> 0 | V24: =$D24*G24 -> 0 | W24: =$D24*H24 -> 0 | X24: =$D24*I24 -> 0 | Y24: =$D24*J24 -> 0 | Z24: =$D24*K24 -> 0 | AA24: =$D24*L24 -> 0 | ... AH24: =$D24*S24 -> 0 | AI24: =AJ24/$AI$2 -> #N/A | AJ24: =SUM(T24:AH24) -> 0
A25: 9 | B25: Óleo do motor - MOPAR MAXPRO SYNTHETIC 0W20 (SP/GF-6A) | C25: K68218951LA_F | D25: =VLOOKUP(C25,'[1]PREÇO ATUAL'!$A:$D,4,0) -> 81.26 | E25: 3.4 | F25: 3.4 | G25: 3.4 | H25: 3.4 | I25: 3.4 | J25: 3.4 | K25: 3.4 | L25: 3.4 | M25: 3.4 | N25: 3.4 | O25: 3.4 | P25: 3.4 | Q25: 3.4 | R25: 3.4 | S25: 3.4 | T25: =$D25*E25 -> 276.284 | U25: =$D25*F25 -> 276.284 | V25: =$D25*G25 -> 276.284 | W25: =$D25*H25 -> 276.284 | X25: =$D25*I25 -> 276.284 | Y25: =$D25*J25 -> 276.284 | Z25: =$D25*K25 -> 276.284 | AA25: =$D25*L25 -> 276.284 | ... AH25: =$D25*S25 -> 276.284 | AI25: =AJ25/$AI$2 -> #N/A | AJ25: =SUM(T25:AH25) -> 4144.26
A26: 10 | B26: Tempo Padrão de Mão-De-Obra [horas] | C26: MO FIAT | D26: =VLOOKUP(C26,'[1]PREÇO ATUAL'!$A:$D,4,0) -> #N/A | E26: 1.05 | F26: 1.4 | G26: 1.1 | H26: 2.4 | I26: 1.2 | J26: 1.65 | K26: 1.05 | L26: 2.4 | M26: 1.1 | N26: 1.55 | O26: 1.05 | P26: 1.7 | Q26: 1.05 | R26: 1.4 | S26: 1.25 | T26: =$D26*E26 -> #N/A | U26: =$D26*F26 -> #N/A | V26: =$D26*G26 -> #N/A | W26: =$D26*H26 -> #N/A | X26: =$D26*I26 -> #N/A | Y26: =$D26*J26 -> #N/A | Z26: =$D26*K26 -> #N/A | AA26: =$D26*L26 -> #N/A | ... AH26: =$D26*S26 -> #N/A | AI26: =AJ26/$AI$2 -> #N/A | AJ26: =SUM(T26:AH26) -> #N/A
A28: CRONOS 1.3 MY27 AT | E28: PLANO DE MANUTENÇÃO | T28: CUSTOS DE MANUTENÇÃO [R$] | AI28: Total
T29: =MROUND(SUM(T31:T39),1) -> #N/A | U29: =MROUND(SUM(U31:U39),1) -> #N/A | V29: =MROUND(SUM(V31:V39),1) -> #N/A | W29: =MROUND(SUM(W31:W39),1) -> #N/A | X29: =MROUND(SUM(X31:X39),1) -> #N/A | Y29: =MROUND(SUM(Y31:Y39),1) -> #N/A | Z29: =MROUND(SUM(Z31:Z39),1) -> #N/A | AA29: =MROUND(SUM(AA31:AA39),1) -> #N/A | ... AH29: =MROUND(SUM(AH31:AH39),1) -> #N/A | AI29: =SUM(T29:AH29) -> #N/A
A30: Nº | B30: ITENS DE SUBSTITUIÇÃO OBRIGATÓRIA | C30: PN | D30: P. PUB. | E30: 1a | F30: 2a | G30: 3a | H30: 4a | I30: 5a | J30: 6a | K30: 7a | L30: 8a | M30: 9a | N30: 10a | O30: 11 | P30: 12 | Q30: 13 | R30: 14 | S30: 15 | T30: 10000 | U30: 20000 | V30: 30000 | W30: 40000 | X30: 50000 | Y30: 60000 | Z30: 70000 | AA30: 80000 | AB30: 90000 | AC30: 100000 | AD30: =AC30+10000 -> 110000 | AE30: =AD30+10000 -> 120000 | AF30: =AE30+10000 -> 130000 | AG30: =AF30+10000 -> 140000 | AH30: =AG30+10000 -> 150000 | AI30: % 100 | AJ30: TTL 100
A31: 1 | B31: Filtro de óleo do motor | C31: 7094709 | D31: =VLOOKUP(C31,'[1]PREÇO ATUAL'!$A:$D,4,0) -> 79.9 | E31: 1 | F31: 1 | G31: 1 | H31: 1 | I31: 1 | J31: 1 | K31: 1 | L31: 1 | M31: 1 | N31: 1 | O31: 1 | P31: 1 | Q31: 1 | R31: 1 | S31: 1 | T31: =$D31*E31 -> 79.9 | U31: =$D31*F31 -> 79.9 | V31: =$D31*G31 -> 79.9 | W31: =$D31*H31 -> 79.9 | X31: =$D31*I31 -> 79.9 | Y31: =$D31*J31 -> 79.9 | Z31: =$D31*K31 -> 79.9 | AA31: =$D31*L31 -> 79.9 | ... AH31: =$D31*S31 -> 79.9 | AI31: =AJ31/$AI$2 -> #N/A | AJ31: =SUM(T31:AH31) -> 1198.5
A32: 2 | B32: Filtro de Combustível | C32: 52162685 | D32: =VLOOKUP(C32,'[1]PREÇO ATUAL'!$A:$D,4,0) -> 35.9 | F32: 1 | H32: 1 | J32: 1 | L32: 1 | N32: 1 | P32: 1 | R32: 1 | T32: =$D32*E32 -> 0 | U32: =$D32*F32 -> 35.9 | V32: =$D32*G32 -> 0 | W32: =$D32*H32 -> 35.9 | X32: =$D32*I32 -> 0 | Y32: =$D32*J32 -> 35.9 | Z32: =$D32*K32 -> 0 | AA32: =$D32*L32 -> 35.9 | ... AH32: =$D32*S32 -> 0 | AI32: =AJ32/$AI$2 -> #N/A | AJ32: =SUM(T32:AH32) -> 251.3
A33: 3 | B33: Elemento do filtro de ar do motor | C33: 52046268 | D33: =VLOOKUP(C33,'[1]PREÇO ATUAL'!$A:$D,4,0) -> 89.9 | F33: 1 | H33: 1 | J33: 1 | L33: 1 | N33: 1 | P33: 1 | R33: 1 | T33: =$D33*E33 -> 0 | U33: =$D33*F33 -> 89.9 | V33: =$D33*G33 -> 0 | W33: =$D33*H33 -> 89.9 | X33: =$D33*I33 -> 0 | Y33: =$D33*J33 -> 89.9 | Z33: =$D33*K33 -> 0 | AA33: =$D33*L33 -> 89.9 | ... AH33: =$D33*S33 -> 0 | AI33: =AJ33/$AI$2 -> #N/A | AJ33: =SUM(T33:AH33) -> 629.3
A34: 4 | B34: Filtro de ar limpo do canister | C34: 7096883 | D34: =VLOOKUP(C34,'[1]PREÇO ATUAL'!$A:$D,4,0) -> 199.05 | E34: 1 | F34: 1 | G34: 1 | H34: 1 | I34: 1 | J34: 1 | K34: 1 | L34: 1 | M34: 1 | N34: 1 | O34: 1 | P34: 1 | Q34: 1 | R34: 1 | S34: 1 | T34: =$D34*E34 -> 199.05 | U34: =$D34*F34 -> 199.05 | V34: =$D34*G34 -> 199.05 | W34: =$D34*H34 -> 199.05 | X34: =$D34*I34 -> 199.05 | Y34: =$D34*J34 -> 199.05 | Z34: =$D34*K34 -> 199.05 | AA34: =$D34*L34 -> 199.05 | ... AH34: =$D34*S34 -> 199.05 | AI34: =AJ34/$AI$2 -> #N/A | AJ34: =SUM(T34:AH34) -> 2985.75
A35: 5 | B35: Velas de ignição do motor (a cada 40.000 km, independente do tempo) | C35: 55267995 | D35: =VLOOKUP(C35,'[1]PREÇO ATUAL'!$A:$D,4,0) -> 175.9 | H35: 4 | L35: 4 | P35: 4 | T35: =$D35*E35 -> 0 | U35: =$D35*F35 -> 0 | V35: =$D35*G35 -> 0 | W35: =$D35*H35 -> 703.6 | X35: =$D35*I35 -> 0 | Y35: =$D35*J35 -> 0 | Z35: =$D35*K35 -> 0 | AA35: =$D35*L35 -> 703.6 | ... AH35: =$D35*S35 -> 0 | AI35: =AJ35/$AI$2 -> #N/A | AJ35: =SUM(T35:AH35) -> 2110.8
A36: 6 | B36: Correia dos órgão auxiliares (a cada 60.000 km ou 4 anos, o que ocorrer primeiro) | C36: 55267966 | D36: =VLOOKUP(C36,'[1]PREÇO ATUAL'!$A:$D,4,0) -> 143.23 | T36: =$D36*E36 -> 0 | U36: =$D36*F36 -> 0 | V36: =$D36*G36 -> 0 | W36: =$D36*H36 -> 0 | X36: =$D36*I36 -> 0 | Y36: =$D36*J36 -> 0 | Z36: =$D36*K36 -> 0 | AA36: =$D36*L36 -> 0 | ... AH36: =$D36*S36 -> 0 | AI36: =AJ36/$AI$2 -> #N/A | AJ36: =SUM(T36:AH36) -> 0
A37: 7 | B37: Fluído de freio (a cada 40.000 km ou 2 anos, ou que ocurrer primeiro) | C37: K04549625LA_F | D37: =VLOOKUP(C37,'[1]PREÇO ATUAL'!$A:$D,4,0) -> 33.622493 | T37: =$D37*E37 -> 0 | U37: =$D37*F37 -> 0 | V37: =$D37*G37 -> 0 | W37: =$D37*H37 -> 0 | X37: =$D37*I37 -> 0 | Y37: =$D37*J37 -> 0 | Z37: =$D37*K37 -> 0 | AA37: =$D37*L37 -> 0 | ... AH37: =$D37*S37 -> 0 | AI37: =AJ37/$AI$2 -> #N/A | AJ37: =SUM(T37:AH37) -> 0
A38: 8 | B38: Óleo do motor - MOPAR MAXPRO SYNTHETIC 0W20 (SP/GF-6A) | C38: K68218951LA_F | D38: =VLOOKUP(C38,'[1]PREÇO ATUAL'!$A:$D,4,0) -> 81.26 | E38: 3.4 | F38: 3.4 | G38: 3.4 | H38: 3.4 | I38: 3.4 | J38: 3.4 | K38: 3.4 | L38: 3.4 | M38: 3.4 | N38: 3.4 | O38: 3.4 | P38: 3.4 | Q38: 3.4 | R38: 3.4 | S38: 3.4 | T38: =$D38*E38 -> 276.284 | U38: =$D38*F38 -> 276.284 | V38: =$D38*G38 -> 276.284 | W38: =$D38*H38 -> 276.284 | X38: =$D38*I38 -> 276.284 | Y38: =$D38*J38 -> 276.284 | Z38: =$D38*K38 -> 276.284 | AA38: =$D38*L38 -> 276.284 | ... AH38: =$D38*S38 -> 276.284 | AI38: =AJ38/$AI$2 -> #N/A | AJ38: =SUM(T38:AH38) -> 4144.26
A39: 9 | B39: Tempo Padrão de Mão-De-Obra [horas] | C39: MO FIAT | D39: =VLOOKUP(C39,'[1]PREÇO ATUAL'!$A:$D,4,0) -> #N/A | E39: 1.05 | F39: 1.4 | G39: 1.1 | H39: 2.4 | I39: 1.2 | J39: 1.65 | K39: 1.05 | L39: 2.4 | M39: 1.1 | N39: 1.55 | O39: 1.05 | P39: 1.7 | Q39: 1.05 | R39: 1.4 | S39: 1.25 | T39: =$D39*E39 -> #N/A | U39: =$D39*F39 -> #N/A | V39: =$D39*G39 -> #N/A | W39: =$D39*H39 -> #N/A | X39: =$D39*I39 -> #N/A | Y39: =$D39*J39 -> #N/A | Z39: =$D39*K39 -> #N/A | AA39: =$D39*L39 -> #N/A | ... AH39: =$D39*S39 -> #N/A | AI39: =AJ39/$AI$2 -> #N/A | AJ39: =SUM(T39:AH39) -> #N/A

Sheet CRONOS 1.8
A1: CRONOS 1.8 | E1: PLANO DE MANUTENÇÃO | T1: CUSTOS DE MANUTENÇÃO [R$] | AI1: Total
T2: =MROUND(SUM(T4:T12),1) -> #N/A | U2: =MROUND(SUM(U4:U12),1) -> #N/A | V2: =MROUND(SUM(V4:V12),1) -> #N/A | W2: =MROUND(SUM(W4:W12),1) -> #N/A | X2: =MROUND(SUM(X4:X12),1) -> #N/A | Y2: =MROUND(SUM(Y4:Y12),1) -> #N/A | Z2: =MROUND(SUM(Z4:Z12),1) -> #N/A | AA2: =MROUND(SUM(AA4:AA12),1) -> #N/A | ... AH2: =MROUND(SUM(AH4:AH12),1) -> #N/A | AI2: =SUM(T2:AH2) -> #N/A
A3: Nº | B3: ITENS DE SUBSTITUIÇÃO OBRIGATÓRIA | C3: PN | D3: P. PUB. | E3: 1a | F3: 2a | G3: 3a | H3: 4a | I3: 5a | J3: 6a | K3: 7a | L3: 8a | M3: 9a | N3: 10a | O3: 11 | P3: 12 | Q3: 13 | R3: 14 | S3: 15 | T3: 10000 | U3: 20000 | V3: 30000 | W3: 40000 | X3: 50000 | Y3: 60000 | Z3: 70000 | AA3: 80000 | AB3: 90000 | AC3: 100000 | AD3: =AC3+10000 -> 110000 | AE3: =AD3+10000 -> 120000 | AF3: =AE3+10000 -> 130000 | AG3: =AF3+10000 -> 140000 | AH3: =AG3+10000 -> 150000 | AI3: % 100 | AJ3: TTL 100
A4: 1 | B4: Filtro de Óleo do Motor | C4: 7087808 | D4: =VLOOKUP(C4,'[1]PREÇO ATUAL'!$A:$D,4,0) -> 41.43 | E4: 1 | F4: 1 | G4: 1 | H4: 1 | I4: 1 | J4: 1 | K4: 1 | L4: 1 | M4: 1 | N4: 1 | O4: 1 | P4: 1 | Q4: 1 | R4: 1 | S4: 1 | T4: =$D4*E4 -> 41.43 | U4: =$D4*F4 -> 41.43 | V4: =$D4*G4 -> 41.43 | W4: =$D4*H4 -> 41.43 | X4: =$D4*I4 -> 41.43 | Y4: =$D4*J4 -> 41.43 | Z4: =$D4*K4 -> 41.43 | AA4: =$D4*L4 -> 41.43 | ... AH4: =$D4*S4 -> 41.43 | AI4: =AJ4/$AI$2 -> #N/A | AJ4: =SUM(T4:AH4) -> 621.45
A5: 2 | B5: Filtro Combustível | C5: 52162685 | D5: =VLOOKUP(C5,'[1]PREÇO ATUAL'!$A:$D,4,0) -> 35.9 | F5: 1 | H5: 1 | J5: 1 | L5: 1 | N5: 1 | P5: 1 | R5: 1 | T5: =$D5*E5 -> 0 | U5: =$D5*F5 -> 35.9 | V5: =$D5*G5 -> 0 | W5: =$D5*H5 -> 35.9 | X5: =$D5*I5 -> 0 | Y5: =$D5*J5 -> 35.9 | Z5: =$D5*K5 -> 0 | AA5: =$D5*L5 -> 35.9 | ... AH5: =$D5*S5 -> 0 | AI5: =AJ5/$AI$2 -> #N/A | AJ5: =SUM(T5:AH5) -> 251.3
A6: 3 | B6: Filtro de Ar | C6: 52062431 | D6: =VLOOKUP(C6,'[1]PREÇO ATUAL'!$A:$D,4,0) -> 84.9 | F6: 1 | H6: 1 | J6: 1 | L6: 1 | N6: 1 | P6: 1 | R6: 1 | T6: =$D6*E6 -> 0 | U6: =$D6*F6 -> 84.9 | V6: =$D6*G6 -> 0 | W6: =$D6*H6 -> 84.9 | X6: =$D6*I6 -> 0 | Y6: =$D6*J6 -> 84.9 | Z6: =$D6*K6 -> 0 | AA6: =$D6*L6 -> 84.9 | ... AH6: =$D6*S6 -> 0 | AI6: =AJ6/$AI$2 -> #N/A | AJ6: =SUM(T6:AH6) -> 594.3
A7: 4 | B7: Vela Ignição | C7: 46348847 | D7: =VLOOKUP(C7,'[1]PREÇO ATUAL'!$A:$D,4,0) -> 114.24 | J7: 4 | P7: 4 | T7: =$D7*E7 -> 0 | U7: =$D7*F7 -> 0 | V7: =$D7*G7 -> 0 | W7: =$D7*H7 -> 0 | X7: =$D7*I7 -> 0 | Y7: =$D7*J7 -> 456.96 | Z7: =$D7*K7 -> 0 | AA7: =$D7*L7 -> 0 | ... AH7: =$D7*S7 -> 0 | AI7: =AJ7/$AI$2 -> #N/A | AJ7: =SUM(T7:AH7) -> 913.92
A8: 5 | B8: Correia dos Orgãos Auxiliares | C8: 55258359 | D8: =VLOOKUP(C8,'[1]PREÇO ATUAL'!$A:$D,4,0) -> 169.01 | J8: 1 | P8: 1 | T8: =$D8*E8 -> 0 | U8: =$D8*F8 -> 0 | V8: =$D8*G8 -> 0 | W8: =$D8*H8 -> 0 | X8: =$D8*I8 -> 0 | Y8: =$D8*J8 -> 169.01 | Z8: =$D8*K8 -> 0 | AA8: =$D8*L8 -> 0 | ... AH8: =$D8*S8 -> 0 | AI8: =AJ8/$AI$2 -> #N/A | AJ8: =SUM(T8:AH8) -> 338.02
A9: 6 | B9: Óleo da caixa de cambio mecanica - SAE 75W – API GL4 | C9: 7095576 | D9: =VLOOKUP(C9,'[1]PREÇO ATUAL'!$A:$D,4,0) -> 165.97812 | P9: 2 | T9: =$D9*E9 -> 0 | U9: =$D9*F9 -> 0 | V9: =$D9*G9 -> 0 | W9: =$D9*H9 -> 0 | X9: =$D9*I9 -> 0 | Y9: =$D9*J9 -> 0 | Z9: =$D9*K9 -> 0 | AA9: =$D9*L9 -> 0 | ... AH9: =$D9*S9 -> 0 | AI9: =AJ9/$AI$2 -> #N/A | AJ9: =SUM(T9:AH9) -> 331.95624
A10: 7 | B10: MOPAR BRAKE FLUID DOT 4 - A cada 2 anos | C10: K04549625LA_F | D10: =VLOOKUP(C10,'[1]PREÇO ATUAL'!$A:$D,4,0) -> 33.622493 | T10: =$D10*E10 -> 0 | U10: =$D10*F10 -> 0 | V10: =$D10*G10 -> 0 | W10: =$D10*H10 -> 0 | X10: =$D10*I10 -> 0 | Y10: =$D10*J10 -> 0 | Z10: =$D10*K10 -> 0 | AA10: =$D10*L10 -> 0 | ... AH10: =$D10*S10 -> 0 | AI10: =AJ10/$AI$2 -> #N/A | AJ10: =SUM(T10:AH10) -> 0
A11: 8 | B11: MOPAR MAXPRO 5W30 (SN/GF-5) | C11: K68218921LA_F | D11: 89.6 | E11: 4.7 | F11: 4.7 | G11: 4.7 | H11: 4.7 | I11: 4.7 | J11: 4.7 | K11: 4.7 | L11: 4.7 | M11: 4.7 | N11: 4.7 | O11: 4.7 | P11: 4.7 | Q11: 4.7 | R11: 4.7 | S11: 4.7 | T11: =$D11*E11 -> 421.12 | U11: =$D11*F11 -> 421.12 | V11: =$D11*G11 -> 421.12 | W11: =$D11*H11 -> 421.12 | X11: =$D11*I11 -> 421.12 | Y11: =$D11*J11 -> 421.12 | Z11: =$D11*K11 -> 421.12 | AA11: =$D11*L11 -> 421.12 | ... AH11: =$D11*S11 -> 421.12 | AI11: =AJ11/$AI$2 -> #N/A | AJ11: =SUM(T11:AH11) -> 6316.8
A12: 9 | B12: Tempo Padrão de Mão-De-Obra [horas] | C12: MO FIAT | D12: =VLOOKUP(C12,'[1]PREÇO ATUAL'!$A:$D,4,0) -> #N/A | E12: 0.85 | F12: 1.2 | G12: 0.9 | H12: 1.65 | I12: 1 | J12: 2.55 | K12: 0.9 | L12: 1.65 | M12: 0.9 | N12: 1.35 | O12: 0.85 | P12: 3.1 | Q12: 0.85 | R12: 1.25 | S12: 1.05 | T12: =D12*E12 -> #N/A | U12: =$D12*F12 -> #N/A | V12: =$D12*G12 -> #N/A | W12: =$D12*H12 -> #N/A | X12: =$D12*I12 -> #N/A | Y12: =$D12*J12 -> #N/A | Z12: =$D12*K12 -> #N/A | AA12: =$D12*L12 -> #N/A | AB12: =$D12*M12 -> #N/A | ... AH12: =$D12*S12 -> #N/A | AI12: =AJ12/$AI$2 -> #N/A | AJ12: =SUM(T12:AH12) -> #N/A

Sheet NOVO UNO 1.0 FIRE
A1: UNO 1.0 FIRE | E1: PLANO DE MANUTENÇÃO | O1: CUSTOS DE MANUTENÇÃO [R$] | Y1: Total
O2: =MROUND(SUM(O4:O13),1) -> #N/A | P2: =MROUND(SUM(P4:P13),1) -> #N/A | Q2: =MROUND(SUM(Q4:Q13),1) -> #N/A | R2: =MROUND(SUM(R4:R13),1) -> #N/A | S2: =MROUND(SUM(S4:S13),1) -> #N/A | T2: =MROUND(SUM(T4:T13),1) -> #N/A | U2: =MROUND(SUM(U4:U13),1) -> #N/A | V2: =MROUND(SUM(V4:V13),1) -> #N/A | ... X2: =MROUND(SUM(X4:X13),1) -> #N/A | Y2: =SUM(O2:X2) -> #N/A
A3: Nº | B3: ITENS DE SUBSTITUIÇÃO OBRIGATÓRIA | C3: PN | D3: P. PUB. | E3: 1a | F3: 2a | G3: 3a | H3: 4a | I3: 5a | J3: 6a | K3: 7a | L3: 8a | M3: 9a | N3: 10a | O3: 10000 | P3: 20000 | Q3: 30000 | R3: 40000 | S3: 50000 | T3: 60000 | U3: 70000 | V3: 80000 | W3: 90000 | X3: 100000 | Y3: % 100 | Z3: TTL 100
A4: 1 | B4: VELA IGNICAO | C4: 46480362 | D4: =VLOOKUP(C4,'[1]PREÇO ATUAL'!$A:$D,4,0) -> 24.15 | G4: 4 | J4: 4 | M4: 4 | O4: =$D4*E4 -> 0 | P4: =$D4*F4 -> 0 | Q4: =$D4*G4 -> 96.6 | R4: =$D4*H4 -> 0 | S4: =$D4*I4 -> 0 | T4: =$D4*J4 -> 96.6 | U4: =$D4*K4 -> 0 | V4: =$D4*L4 -> 0 | ... X4: =$D4*N4 -> 0 | Y4: =Z4/$Y$2 -> #N/A | Z4: =SUM(O4:X4) -> 289.8
A5: 2 | B5: CORREIA DISTRIBUICAO | C5: 46337687 | D5: =VLOOKUP(C5,'[1]PREÇO ATUAL'!$A:$D,4,0) -> 136.4 | J5: 1 | O5: =$D5*E5 -> 0 | P5: =$D5*F5 -> 0 | Q5: =$D5*G5 -> 0 | R5: =$D5*H5 -> 0 | S5: =$D5*I5 -> 0 | T5: =$D5*J5 -> 136.4 | U5: =$D5*K5 -> 0 | V5: =$D5*L5 -> 0 | ... X5: =$D5*N5 -> 0 | Y5: =Z5/$Y$2 -> #N/A | Z5: =SUM(O5:X5) -> 136.4
A6: 3 | B6: FILTRO OLEO | C6: 46751179 | D6: =VLOOKUP(C6,'[1]PREÇO ATUAL'!$A:$D,4,0) -> 71.2 | E6: 1 | F6: 1 | G6: 1 | H6: 1 | I6: 1 | J6: 1 | K6: 1 | L6: 1 | M6: 1 | N6: 1 | O6: =$D6*E6 -> 71.2 | P6: =$D6*F6 -> 71.2 | Q6: =$D6*G6 -> 71.2 | R6: =$D6*H6 -> 71.2 | S6: =$D6*I6 -> 71.2 | T6: =$D6*J6 -> 71.2 | U6: =$D6*K6 -> 71.2 | V6: =$D6*L6 -> 71.2 | ... X6: =$D6*N6 -> 71.2 | Y6: =Z6/$Y$2 -> #N/A | Z6: =SUM(O6:X6) -> 712
A7: 4 | B7: FILTRO COMBUSTIVEL | C7: 52162685 | D7: =VLOOKUP(C7,'[1]PREÇO ATUAL'!$A:$D,4,0) -> 35.9 | F7: 1 | H7: 1 | J7: 1 | L7: 1 | N7: 1 | O7: =$D7*E7 -> 0 | P7: =$D7*F7 -> 35.9 | Q7: =$D7*G7 -> 0 | R7: =$D7*H7 -> 35.9 | S7: =$D7*I7 -> 0 | T7: =$D7*J7 -> 35.9 | U7: =$D7*K7 -> 0 | V7: =$D7*L7 -> 35.9 | ... X7: =$D7*N7 -> 35.9 | Y7: =Z7/$Y$2 -> #N/A | Z7: =SUM(O7:X7) -> 179.5
A8: 5 | B8: ELEMENTO FILTRANTE | C8: 51854598 | D8: =VLOOKUP(C8,'[1]PREÇO ATUAL'!$A:$D,4,0) -> 83.06 | F8: 1 | H8: 1 | J8: 1 | L8: 1 | N8: 1 | O8: =$D8*E8 -> 0 | P8: =$D8*F8 -> 83.06 | Q8: =$D8*G8 -> 0 | R8: =$D8*H8 -> 83.06 | S8: =$D8*I8 -> 0 | T8: =$D8*J8 -> 83.06 | U8: =$D8*K8 -> 0 | V8: =$D8*L8 -> 83.06 | ... X8: =$D8*N8 -> 83.06 | Y8: =Z8/$Y$2 -> #N/A | Z8: =SUM(O8:X8) -> 415.3
A9: 6 | B9: CORREIA TRANSMISSAO C/ AC | C9: 55236185 | D9: =VLOOKUP(C9,'[1]PREÇO ATUAL'!$A:$D,4,0) -> 139.9 | J9: 1 | O9: =$D9*E9 -> 0 | P9: =$D9*F9 -> 0 | Q9: =$D9*G9 -> 0 | R9: =$D9*H9 -> 0 | S9: =$D9*I9 -> 0 | T9: =$D9*J9 -> 139.9 | U9: =$D9*K9 -> 0 | V9: =$D9*L9 -> 0 | ... X9: =$D9*N9 -> 0 | Y9: =Z9/$Y$2 -> #N/A | Z9: =SUM(O9:X9) -> 139.9
A10: 7 | B10: CORREIA TRANSMISSAO DH | C10: 46744566 | D10: =VLOOKUP(C10,'[1]PREÇO ATUAL'!$A:$D,4,0) -> 25.55 | J10: 1 | O10: =$D10*E10 -> 0 | P10: =$D10*F10 -> 0 | Q10: =$D10*G10 -> 0 | R10: =$D10*H10 -> 0 | S10: =$D10*I10 -> 0 | T10: =$D10*J10 -> 25.55 | U10: =$D10*K10 -> 0 | V10: =$D10*L10 -> 0 | ... X10: =$D10*N10 -> 0 | Y10: =Z10/$Y$2 -> #N/A | Z10: =SUM(O10:X10) -> 25.55
A11: 8 | B11: MOPAR MAXPRO 5W30 (SN/GF-5) | C11: K68218921LA_F | D11: 89.6 | E11: 2.8 | F11: 2.8 | G11: 2.8 | H11: 2.8 | I11: 2.8 | J11: 2.8 | K11: 2.8 | L11: 2.8 | M11: 2.8 | N11: 2.8 | O11: =$D11*E11 -> 250.88 | P11: =$D11*F11 -> 250.88 | Q11: =$D11*G11 -> 250.88 | R11: =$D11*H11 -> 250.88 | S11: =$D11*I11 -> 250.88 | T11: =$D11*J11 -> 250.88 | U11: =$D11*K11 -> 250.88 | V11: =$D11*L11 -> 250.88 | ... X11: =$D11*N11 -> 250.88 | Y11: =Z11/$Y$2 -> #N/A | Z11: =SUM(O11:X11) -> 2508.8
A12: 9 | B12: MOPAR BRAKE FLUID DOT 4 - A cada 2 anos | C12: K04549625LA_F | D12: =VLOOKUP(C12,'[1]PREÇO ATUAL'!$A:$D,4,0) -> 33.622493 | O12: =$D12*E12 -> 0 | P12: =$D12*F12 -> 0 | Q12: =$D12*G12 -> 0 | R12: =$D12*H12 -> 0 | S12: =$D12*I12 -> 0 | T12: =$D12*J12 -> 0 | U12: =$D12*K12 -> 0 | V12: =$D12*L12 -> 0 | ... X12: =$D12*N12 -> 0 | Y12: =Z12/$Y$2 -> #N/A | Z12: =SUM(O12:X12) -> 0
A13: 10 | B13: Tempo Padrão de Mão-De-Obra [horas] | C13: MO FIAT | D13: =VLOOKUP(C13,'[1]PREÇO ATUAL'!$A:$D,4,0) -> #N/A | E13: 0.95 | F13: 1.2 | G13: 2.1 | H13: 1.5 | I13: 1.15 | J13: 4.4 | K13: 0.95 | L13: 1.5 | M13: 2.1 | N13: 1.3 | O13: =D13*E13 -> #N/A | P13: =$D13*F13 -> #N/A | Q13: =$D13*G13 -> #N/A | R13: =$D13*H13 -> #N/A | S13: =$D13*I13 -> #N/A | T13: =$D13*J13 -> #N/A | U13: =$D13*K13 -> #N/A | V13: =$D13*L13 -> #N/A | W13: =$D13*M13 -> #N/A | X13: =$D13*N13 -> #N/A | Y13: =Z13/$Y$2 -> #N/A | Z13: =SUM(O13:X13) -> #N/A

Sheet NOVO UNO 1.0 FIREFLY
A1: UNO 1.0 FIREFLY | E1: PLANO DE MANUTENÇÃO | O1: CUSTOS DE MANUTENÇÃO [R$] | Y1: Total
O2: =MROUND(SUM(O4:O11),1) -> #N/A | P2: =MROUND(SUM(P4:P11),1) -> #N/A | Q2: =MROUND(SUM(Q4:Q11),1) -> #N/A | R2: =MROUND(SUM(R4:R11),1) -> #N/A | S2: =MROUND(SUM(S4:S11),1) -> #N/A | T2: =MROUND(SUM(T4:T11),1) -> #N/A | U2: =MROUND(SUM(U4:U11),1) -> #N/A | V2: =MROUND(SUM(V4:V11),1) -> #N/A | ... X2: =MROUND(SUM(X4:X11),1) -> #N/A | Y2: =SUM(O2:X2) -> #N/A
A3: Nº | B3: ITENS DE SUBSTITUIÇÃO OBRIGATÓRIA | C3: PN | D3: P. PUB. | E3: 1a | F3: 2a | G3: 3a | H3: 4a | I3: 5a | J3: 6a | K3: 7a | L3: 8a | M3: 9a | N3: 10a | O3: 10000 | P3: 20000 | Q3: 30000 | R3: 40000 | S3: 50000 | T3: 60000 | U3: 70000 | V3: 80000 | W3: 90000 | X3: 100000 | Y3: % 100 | Z3: TTL 100
A4: 1 | B4: Filtro de Óleo do Motor | C4: 7094709 | D4: =VLOOKUP(C4,'[1]PREÇO ATUAL'!$A:$D,4,0) -> 79.9 | E4: 1 | F4: 1 | G4: 1 | H4: 1 | I4: 1 | J4: 1 | K4: 1 | L4: 1 | M4: 1 | N4: 1 | O4: =$D4*E4 -> 79.9 | P4: =$D4*F4 -> 79.9 | Q4: =$D4*G4 -> 79.9 | R4: =$D4*H4 -> 79.9 | S4: =$D4*I4 -> 79.9 | T4: =$D4*J4 -> 79.9 | U4: =$D4*K4 -> 79.9 | V4: =$D4*L4 -> 79.9 | ... X4: =$D4*N4 -> 79.9 | Y4: =Z4/$Y$2 -> #N/A | Z4: =SUM(O4:X4) -> 799
A5: 2 | B5: Filtro de Combustível | C5: 52162685 | D5: =VLOOKUP(C5,'[1]PREÇO ATUAL'!$A:$D,4,0) -> 35.9 | F5: 1 | H5: 1 | J5: 1 | L5: 1 | N5: 1 | O5: =$D5*E5 -> 0 | P5: =$D5*F5 -> 35.9 | Q5: =$D5*G5 -> 0 | R5: =$D5*H5 -> 35.9 | S5: =$D5*I5 -> 0 | T5: =$D5*J5 -> 35.9 | U5: =$D5*K5 -> 0 | V5: =$D5*L5 -> 35.9 | ... X5: =$D5*N5 -> 35.9 | Y5: =Z5/$Y$2 -> #N/A | Z5: =SUM(O5:X5) -> 179.5
A6: 3 | B6: Filtro de Ar | C6: 52046268 | D6: =VLOOKUP(C6,'[1]PREÇO ATUAL'!$A:$D,4,0) -> 89.9 | F6: 1 | H6: 1 | J6: 1 | L6: 1 | N6: 1 | O6: =$D6*E6 -> 0 | P6: =$D6*F6 -> 89.9 | Q6: =$D6*G6 -> 0 | R6: =$D6*H6 -> 89.9 | S6: =$D6*I6 -> 0 | T6: =$D6*J6 -> 89.9 | U6: =$D6*K6 -> 0 | V6: =$D6*L6 -> 89.9 | ... X6: =$D6*N6 -> 89.9 | Y6: =Z6/$Y$2 -> #N/A | Z6: =SUM(O6:X6) -> 449.5
A7: 4 | B7: Vela de Ignição | C7: 55267995 | D7: =VLOOKUP(C7,'[1]PREÇO ATUAL'!$A:$D,4,0) -> 175.9 | H7: 3 | L7: 3 | O7: =$D7*E7 -> 0 | P7: =$D7*F7 -> 0 | Q7: =$D7*G7 -> 0 | R7: =$D7*H7 -> 527.7 | S7: =$D7*I7 -> 0 | T7: =$D7*J7 -> 0 | U7: =$D7*K7 -> 0 | V7: =$D7*L7 -> 527.7 | ... X7: =$D7*N7 -> 0 | Y7: =Z7/$Y$2 -> #N/A | Z7: =SUM(O7:X7) -> 1055.4
A8: 5 | B8: Correia dos Órgãos Auxiliares | C8: 55267966 | D8: =VLOOKUP(C8,'[1]PREÇO ATUAL'!$A:$D,4,0) -> 143.23 | J8: 1 | O8: =$D8*E8 -> 0 | P8: =$D8*F8 -> 0 | Q8: =$D8*G8 -> 0 | R8: =$D8*H8 -> 0 | S8: =$D8*I8 -> 0 | T8: =$D8*J8 -> 143.23 | U8: =$D8*K8 -> 0 | V8: =$D8*L8 -> 0 | ... X8: =$D8*N8 -> 0 | Y8: =Z8/$Y$2 -> #N/A | Z8: =SUM(O8:X8) -> 143.23
A9: 6 | B9: MOPAR BRAKE FLUID DOT 4 - A cada 2 anos | C9: K04549625LA_F | D9: =VLOOKUP(C9,'[1]PREÇO ATUAL'!$A:$D,4,0) -> 33.622493 | O9: =$D9*E9 -> 0 | P9: =$D9*F9 -> 0 | Q9: =$D9*G9 -> 0 | R9: =$D9*H9 -> 0 | S9: =$D9*I9 -> 0 | T9: =$D9*J9 -> 0 | U9: =$D9*K9 -> 0 | V9: =$D9*L9 -> 0 | ... X9: =$D9*N9 -> 0 | Y9: =Z9/$Y$2 -> #N/A | Z9: =SUM(O9:X9) -> 0
A10: 7 | B10: MOPAR MAXPRO SYNTHETIC 0W20 (SP/GF-6A) | C10: K68218951LA_F | D10: =VLOOKUP(C10,'[1]PREÇO ATUAL'!$A:$D,4,0) -> 81.26 | E10: 2.54 | F10: 2.54 | G10: 2.54 | H10: 2.54 | I10: 2.54 | J10: 2.54 | K10: 2.54 | L10: 2.54 | M10: 2.54 | N10: 2.54 | O10: =$D10*E10 -> 206.4004 | P10: =$D10*F10 -> 206.4004 | Q10: =$D10*G10 -> 206.4004 | R10: =$D10*H10 -> 206.4004 | S10: =$D10*I10 -> 206.4004 | T10: =$D10*J10 -> 206.4004 | U10: =$D10*K10 -> 206.4004 | V10: =$D10*L10 -> 206.4004 | ... X10: =$D10*N10 -> 206.4004 | Y10: =Z10/$Y$2 -> #N/A | Z10: =SUM(O10:X10) -> 2064.004
A11: 8 | B11: Tempo Padrão de Mão-De-Obra [horas] | C11: MO FIAT | D11: =VLOOKUP(C11,'[1]PREÇO ATUAL'!$A:$D,4,0) -> #N/A | E11: 0.85 | F11: 1.1 | G11: 0.95 | H11: 1.4 | I11: 1 | J11: 1.8 | K11: 0.85 | L11: 1.4 | M11: 0.95 | N11: 1.25 | O11: =D11*E11 -> #N/A | P11: =$D11*F11 -> #N/A | Q11: =$D11*G11 -> #N/A | R11: =$D11*H11 -> #N/A | S11: =$D11*I11 -> #N/A | T11: =$D11*J11 -> #N/A | U11: =$D11*K11 -> #N/A | V11: =$D11*L11 -> #N/A | W11: =$D11*M11 -> #N/A | X11: =$D11*N11 -> #N/A | Y11: =Z11/$Y$2 -> #N/A | Z11: =SUM(O11:X11) -> #N/A

Sheet NOVO UNO 1.3 FIREFLY
A1: UNO 1.3 FIREFLY | E1: PLANO DE MANUTENÇÃO | O1: CUSTOS DE MANUTENÇÃO [R$] | Y1: Total
O2: =MROUND(SUM(O4:O11),1) -> #N/A | P2: =MROUND(SUM(P4:P11),1) -> #N/A | Q2: =MROUND(SUM(Q4:Q11),1) -> #N/A | R2: =MROUND(SUM(R4:R11),1) -> #N/A | S2: =MROUND(SUM(S4:S11),1) -> #N/A | T2: =MROUND(SUM(T4:T11),1) -> #N/A | U2: =MROUND(SUM(U4:U11),1) -> #N/A | V2: =MROUND(SUM(V4:V11),1) -> #N/A | ... X2: =MROUND(SUM(X4:X11),1) -> #N/A | Y2: =SUM(O2:X2) -> #N/A
A3: Nº | B3: ITENS DE SUBSTITUIÇÃO OBRIGATÓRIA | C3: PN | D3: P. PUB. | E3: 1a | F3: 2a | G3: 3a | H3: 4a | I3: 5a | J3: 6a | K3: 7a | L3: 8a | M3: 9a | N3: 10a | O3: 10000 | P3: 20000 | Q3: 30000 | R3: 40000 | S3: 50000 | T3: 60000 | U3: 70000 | V3: 80000 | W3: 90000 | X3: 100000 | Y3: % 100 | Z3: TTL 100
A4: 1 | B4: Filtro de Óleo do Motor | C4: 7094709 | D4: =VLOOKUP(C4,'[1]PREÇO ATUAL'!$A:$D,4,0) -> 79.9 | E4: 1 | F4: 1 | G4: 1 | H4: 1 | I4: 1 | J4: 1 | K4: 1 | L4: 1 | M4: 1 | N4: 1 | O4: =$D4*E4 -> 79.9 | P4: =$D4*F4 -> 79.9 | Q4: =$D4*G4 -> 79.9 | R4: =$D4*H4 -> 79.9 | S4: =$D4*I4 -> 79.9 | T4: =$D4*J4 -> 79.9 | U4: =$D4*K4 -> 79.9 | V4: =$D4*L4 -> 79.9 | ... X4: =$D4*N4 -> 79.9 | Y4: =Z4/$Y$2 -> #N/A | Z4: =SUM(O4:X4) -> 799
A5: 2 | B5: Filtro de Combustível | C5: 52162685 | D5: =VLOOKUP(C5,'[1]PREÇO ATUAL'!$A:$D,4,0) -> 35.9 | F5: 1 | H5: 1 | J5: 1 | L5: 1 | N5: 1 | O5: =$D5*E5 -> 0 | P5: =$D5*F5 -> 35.9 | Q5: =$D5*G5 -> 0 | R5: =$D5*H5 -> 35.9 | S5: =$D5*I5 -> 0 | T5: =$D5*J5 -> 35.9 | U5: =$D5*K5 -> 0 | V5: =$D5*L5 -> 35.9 | ... X5: =$D5*N5 -> 35.9 | Y5: =Z5/$Y$2 -> #N/A | Z5: =SUM(O5:X5) -> 179.5
A6: 3 | B6: Filtro de Ar | C6: 52046268 | D6: =VLOOKUP(C6,'[1]PREÇO ATUAL'!$A:$D,4,0) -> 89.9 | F6: 1 | H6: 1 | J6: 1 | L6: 1 | N6: 1 | O6: =$D6*E6 -> 0 | P6: =$D6*F6 -> 89.9 | Q6: =$D6*G6 -> 0 | R6: =$D6*H6 -> 89.9 | S6: =$D6*I6 -> 0 | T6: =$D6*J6 -> 89.9 | U6: =$D6*K6 -> 0 | V6: =$D6*L6 -> 89.9 | ... X6: =$D6*N6 -> 89.9 | Y6: =Z6/$Y$2 -> #N/A | Z6: =SUM(O6:X6) -> 449.5
A7: 4 | B7: Vela de Ignição | C7: 55267995 | D7: =VLOOKUP(C7,'[1]PREÇO ATUAL'!$A:$D,4,0) -> 175.9 | H7: 4 | L7: 4 | O7: =$D7*E7 -> 0 | P7: =$D7*F7 -> 0 | Q7: =$D7*G7 -> 0 | R7: =$D7*H7 -> 703.6 | S7: =$D7*I7 -> 0 | T7: =$D7*J7 -> 0 | U7: =$D7*K7 -> 0 | V7: =$D7*L7 -> 703.6 | ... X7: =$D7*N7 -> 0 | Y7: =Z7/$Y$2 -> #N/A | Z7: =SUM(O7:X7) -> 1407.2
A8: 5 | B8: Correia dos Órgãos Auxiliares | C8: 55267966 | D8: =VLOOKUP(C8,'[1]PREÇO ATUAL'!$A:$D,4,0) -> 143.23 | J8: 1 | O8: =$D8*E8 -> 0 | P8: =$D8*F8 -> 0 | Q8: =$D8*G8 -> 0 | R8: =$D8*H8 -> 0 | S8: =$D8*I8 -> 0 | T8: =$D8*J8 -> 143.23 | U8: =$D8*K8 -> 0 | V8: =$D8*L8 -> 0 | ... X8: =$D8*N8 -> 0 | Y8: =Z8/$Y$2 -> #N/A | Z8: =SUM(O8:X8) -> 143.23
